Workbook
Name TRANSMUTATION_TABLE: 'DO NOT DELETE'!$G$2:$J$42

Sheet INPUT DATA
A1: Input Data Sheet for E-Class Record
C4: REGION | L4: DIVISION | T4: DISTRICT
B5: SCHOOL NAME | T5: SCHOOL ID | AD5: SCHOOL YEAR
A7: FIRST QUARTER | F7: GRADE & SECTION: | Q7: TEACHER:
B8: LEARNERS' NAMES
B11: MALE
A12: 1 | B12: Ang Eli Noah, Adlawan | D12: 0 | E12: 0
A13: 2 | B13: 2.Arcillas, Riley Crilo | D13: 0 | E13: 0
A14: 3 | B14: 3.Haspe, Matt Austin Canvas | D14: 0 | E14: 0
A15: 4 | B15: 4.Lacbain, Kylle Marx Lim | D15: 0 | E15: 0
A16: 5 | B16: 5.Laurio, Xeon Jae Chico | D16: 0 | E16: 0
A17: 6 | B17: 6.Napuran, Thom Brenden Martecio | D17: 0 | E17: 0
A18: 7 | B18: 7.Rosinas, Nathaniel John | D18: 0 | E18: 0
A19: 8 | B19: 8.Salazar, Ulrich Gabrielle Asaytona | D19: 0 | E19: 0
A20: 9 | B20: 9.Santos, Sean Daniel Diopines | D20: 0 | E20: 0
A21: 10 | B21: 10.Soriano, Zegen Khaleb C. | D21: 0 | E21: 0
A22: 11 | C22: 0 | D22: 0 | E22: 0
A23: 12 | C23: 0 | D23: 0 | E23: 0
A24: 13 | B24: FEMALE
A25: 14 | B25: 1. Algabre, Sophia Ysabelle Dagle
A26: 15 | B26: 2. Bade, Myel Ellyre, Bernales
A27: 16 | B27: 3. Bangcal, Colynn Dela Rosa
A28: 17 | B28: 4. Caballero, Amber Yasha, Omambac
A29: 18 | B29: 5.Calilan, Olivia Mula
A30: 19 | B30: 6.Facundo, Aleena
A31: 20 | B31: 7.Ferriols, Francine Faith
A32: 21 | B32: 8.Tagalog, Eysa Duron
A33: 22 | C33: 0 | D33: 0 | E33: 0
A34: 23 | C34: 0 | D34: 0 | E34: 0
A35: 24 | C35: 0 | D35: 0 | E35: 0
A36: 25 | C36: 0 | D36: 0 | E36: 0
A37: 26 | C37: 0 | D37: 0 | E37: 0
A38: 27 | C38: 0 | D38: 0 | E38: 0
A39: 28 | C39: 0 | D39: 0 | E39: 0
A40: 29 | C40: 0 | D40: 0 | E40: 0
A41: 30 | C41: 0 | D41: 0 | E41: 0
A42: 31 | C42: 0 | D42: 0 | E42: 0
A43: 32 | C43: 0 | D43: 0 | E43: 0
A44: 33 | C44: 0 | D44: 0 | E44: 0
... A61: 50 | C61: 0 | D61: 0 | E61: 0
...

Sheet ENGLISH
A1: Class Record
A3: (Pursuant to Deped Order 8 series of 2015)
C4: REGION | G4: ='INPUT DATA'!G4 -> 0 | L4: DIVISION | O4: ='INPUT DATA'!O4 -> 0 | T4: DISTRICT | X4: ='INPUT DATA'!X4 -> 0
B5: SCHOOL NAME | G5: TORIL UCCP LEARNING CENTER INC. | T5: SCHOOL ID | X5: ='INPUT DATA'!X5 -> 0 | AD5: SCHOOL YEAR | AG5: 2025-2026
A7: FIRST QUARTER | F7: GRADE & SECTION: | K7: 2-JACOB | Q7: TEACHER: | S7: PRINANIEL A. ROSALITA | AC7: SUBJECT: | AG7: ENGLISH
B8: LEARNERS' NAMES | F8: WRITTEN WORKS (30%) | S8: PERFORMANCE TASKS (50%) | AF8: QUARTERLY ASSESSMENT (20%) | AI8: Initial | AJ8: Quarterly
F9: 1 | G9: 45856 | H9: July 22 2025 | I9: 45867 | J9: 45881 | K9: August 14 2025 | L9: August 18 2025 | M9: 45895 | N9: summative | O9: P.E | P9: Total | Q9: PS | R9: WS | S9: OR | T9: Attendance | U9: sorting task | V9: Story Reading | W9: Spelling | X9: video clip verb | Y9: 7 | Z9: 8 | AA9: 9 | AB9: 10 | AC9: Total | AD9: PS | AE9: WS | AF9: 1 | AG9: PS | AH9: WS | AI9: Grade | AJ9: Grade
B10: HIGHEST POSSIBLE SCORE | F10: 10 | G10: 10 | H10: 20 | I10: 15 | J10: 10 | K10: 15 | L10: 10 | M10: 20 | N10: 10 | O10: 20 | P10: =IF(COUNT($F10:$O10)=0,"",SUM($F10:$O10)) -> 140 | Q10: 100 | R10: 0.3 | S10: 20 | T10: 10 | U10: 10 | V10: 20 | W10: 20 | X10: 20 | AC10: =IF(COUNT($S10:$AB10)=0,"",SUM($S10:$AB10)) -> 100 | AD10: 100 | AE10: 0.5 | AF10: 25 | AG10: 100 | AH10: 0.2
B11: MALE
A12: 1 | B12: ='INPUT DATA'!B12 -> Ang Eli Noah, Adlawan | F12: 10 | G12: 9 | H12: 19 | I12: 14 | J12: 10 | K12: 15 | L12: 8 | M12: 18 | N12: 10 | O12: 19 | P12: =IF(COUNT($F12:$O12)=0,"",SUM($F12:$O12)) -> 132 | Q12: =IF(ISERROR(IF($P12="","",ROUND(($P12/$P$10)*$Q$10,2))),"",IF($P12="","",ROUND(($P12/$P$10)*$Q$10,2))) -> 94.29 | R12: =IF($Q12="","",ROUND($Q12*$R$10,2)) -> 28.29 | S12: 18 | T12: 10 | U12: 7 | V12: 20 | W12: 20 | X12: 20 | AC12: =IF(COUNT($S12:$AB12)=0,"",SUM($S12:$AB12)) -> 95 | AD12: =IF(ISERROR(IF($AC12="","",ROUND(($AC12/$AC$10)*$AD$10,2))),"",IF($AC12="","",ROUND(($AC12/$AC$10)*$AD$10,2))) -> 95 | AE12: =IF($AD12="","",ROUND($AD12*$AE$10,2)) -> 47.5 | AF12: 24 | AG12: =IF(ISERROR(IF($AF12="","",ROUND(($AF12/$AF$10)*$AG$10,2))),"",IF($AF12="","",ROUND(($AF12/$AF$10)*$AG$10,2))) -> 96 | AH12: =IF($AG12="","",ROUND($AG12*$AH$10,2)) -> 19.2 | AI12: =IF(ISERROR(IF($AF12="","",ROUND(SUM($R12,$AE12,$AH12),2))),"",IF($AF12="","",ROUND(SUM($R12,$AE12,$AH12),2))) -> 94.99 | AJ12: =IF(ISERROR(IF($AF12="","",VLOOKUP(AI12,TRANSMUTATION_TABLE,4,TRUE))),"",IF($AF12="","",VLOOKUP(AI12,TRANSMUTATION_TABLE,4,TRUE))) -> 96
A13: 2 | B13: ='INPUT DATA'!B13 -> 2.Arcillas, Riley Crilo | F13: 10 | G13: 9 | H13: 18 | I13: 15 | J13: 10 | K13: 15 | L13: 9 | M13: 18 | N13: 9 | O13: 19 | P13: =IF(COUNT($F13:$O13)=0,"",SUM($F13:$O13)) -> 132 | Q13: =IF(ISERROR(IF($P13="","",ROUND(($P13/$P$10)*$Q$10,2))),"",IF($P13="","",ROUND(($P13/$P$10)*$Q$10,2))) -> 94.29 | R13: =IF($Q13="","",ROUND($Q13*$R$10,2)) -> 28.29 | S13: 20 | T13: 9 | U13: 7 | V13: 20 | W13: 18 | X13: 20 | AC13: =IF(COUNT($S13:$AB13)=0,"",SUM($S13:$AB13)) -> 94 | AD13: =IF(ISERROR(IF($AC13="","",ROUND(($AC13/$AC$10)*$AD$10,2))),"",IF($AC13="","",ROUND(($AC13/$AC$10)*$AD$10,2))) -> 94 | AE13: =IF($AD13="","",ROUND($AD13*$AE$10,2)) -> 47 | AF13: 24 | AG13: =IF(ISERROR(IF($AF13="","",ROUND(($AF13/$AF$10)*$AG$10,2))),"",IF($AF13="","",ROUND(($AF13/$AF$10)*$AG$10,2))) -> 96 | AH13: =IF($AG13="","",ROUND($AG13*$AH$10,2)) -> 19.2 | AI13: =IF(ISERROR(IF($AF13="","",ROUND(SUM($R13,$AE13,$AH13),2))),"",IF($AF13="","",ROUND(SUM($R13,$AE13,$AH13),2))) -> 94.49 | AJ13: =IF(ISERROR(IF($AF13="","",VLOOKUP(AI13,TRANSMUTATION_TABLE,4,TRUE))),"",IF($AF13="","",VLOOKUP(AI13,TRANSMUTATION_TABLE,4,TRUE))) -> 96
A14: 3 | B14: ='INPUT DATA'!B14 -> 3.Haspe, Matt Austin Canvas | F14: 9 | G14: 10 | H14: 19 | I14: 13 | J14: 10 | K14: 12 | L14: 9 | M14: 15 | N14: 5 | O14: 16 | P14: =IF(COUNT($F14:$O14)=0,"",SUM($F14:$O14)) -> 118 | Q14: =IF(ISERROR(IF($P14="","",ROUND(($P14/$P$10)*$Q$10,2))),"",IF($P14="","",ROUND(($P14/$P$10)*$Q$10,2))) -> 84.29 | R14: =IF($Q14="","",ROUND($Q14*$R$10,2)) -> 25.29 | S14: 18 | T14: 8 | U14: 8 | V14: 20 | W14: 19 | X14: 20 | AC14: =IF(COUNT($S14:$AB14)=0,"",SUM($S14:$AB14)) -> 93 | AD14: =IF(ISERROR(IF($AC14="","",ROUND(($AC14/$AC$10)*$AD$10,2))),"",IF($AC14="","",ROUND(($AC14/$AC$10)*$AD$10,2))) -> 93 | AE14: =IF($AD14="","",ROUND($AD14*$AE$10,2)) -> 46.5 | AF14: 24 | AG14: =IF(ISERROR(IF($AF14="","",ROUND(($AF14/$AF$10)*$AG$10,2))),"",IF($AF14="","",ROUND(($AF14/$AF$10)*$AG$10,2))) -> 96 | AH14: =IF($AG14="","",ROUND($AG14*$AH$10,2)) -> 19.2 | AI14: =IF(ISERROR(IF($AF14="","",ROUND(SUM($R14,$AE14,$AH14),2))),"",IF($AF14="","",ROUND(SUM($R14,$AE14,$AH14),2))) -> 90.99 | AJ14: =IF(ISERROR(IF($AF14="","",VLOOKUP(AI14,TRANSMUTATION_TABLE,4,TRUE))),"",IF($AF14="","",VLOOKUP(AI14,TRANSMUTATION_TABLE,4,TRUE))) -> 94
A15: 4 | B15: ='INPUT DATA'!B15 -> 4.Lacbain, Kylle Marx Lim | F15: 7 | G15: 5 | H15: 20 | I15: 15 | J15: 10 | K15: 14 | L15: 6 | M15: 14 | N15: 8 | O15: 15 | P15: =IF(COUNT($F15:$O15)=0,"",SUM($F15:$O15)) -> 114 | Q15: =IF(ISERROR(IF($P15="","",ROUND(($P15/$P$10)*$Q$10,2))),"",IF($P15="","",ROUND(($P15/$P$10)*$Q$10,2))) -> 81.43 | R15: =IF($Q15="","",ROUND($Q15*$R$10,2)) -> 24.43 | S15: 20 | T15: 9 | U15: 8 | V15: 20 | W15: 20 | X15: 20 | AC15: =IF(COUNT($S15:$AB15)=0,"",SUM($S15:$AB15)) -> 97 | AD15: =IF(ISERROR(IF($AC15="","",ROUND(($AC15/$AC$10)*$AD$10,2))),"",IF($AC15="","",ROUND(($AC15/$AC$10)*$AD$10,2))) -> 97 | AE15: =IF($AD15="","",ROUND($AD15*$AE$10,2)) -> 48.5 | AF15: 25 | AG15: =IF(ISERROR(IF($AF15="","",ROUND(($AF15/$AF$10)*$AG$10,2))),"",IF($AF15="","",ROUND(($AF15/$AF$10)*$AG$10,2))) -> 100 | AH15: =IF($AG15="","",ROUND($AG15*$AH$10,2)) -> 20 | AI15: =IF(ISERROR(IF($AF15="","",ROUND(SUM($R15,$AE15,$AH15),2))),"",IF($AF15="","",ROUND(SUM($R15,$AE15,$AH15),2))) -> 92.93 | AJ15: =IF(ISERROR(IF($AF15="","",VLOOKUP(AI15,TRANSMUTATION_TABLE,4,TRUE))),"",IF($AF15="","",VLOOKUP(AI15,TRANSMUTATION_TABLE,4,TRUE))) -> 95
A16: 5 | B16: ='INPUT DATA'!B16 -> 5.Laurio, Xeon Jae Chico | F16: 9 | G16: 6 | H16: 19 | I16: 13 | J16: 9 | K16: 15 | L16: 8 | M16: 18 | N16: 9 | O16: 18 | P16: =IF(COUNT($F16:$O16)=0,"",SUM($F16:$O16)) -> 124 | Q16: =IF(ISERROR(IF($P16="","",ROUND(($P16/$P$10)*$Q$10,2))),"",IF($P16="","",ROUND(($P16/$P$10)*$Q$10,2))) -> 88.57 | R16: =IF($Q16="","",ROUND($Q16*$R$10,2)) -> 26.57 | S16: 20 | T16: 10 | U16: 9 | V16: 20 | W16: 20 | X16: 20 | AC16: =IF(COUNT($S16:$AB16)=0,"",SUM($S16:$AB16)) -> 99 | AD16: =IF(ISERROR(IF($AC16="","",ROUND(($AC16/$AC$10)*$AD$10,2))),"",IF($AC16="","",ROUND(($AC16/$AC$10)*$AD$10,2))) -> 99 | AE16: =IF($AD16="","",ROUND($AD16*$AE$10,2)) -> 49.5 | AF16: 25 | AG16: =IF(ISERROR(IF($AF16="","",ROUND(($AF16/$AF$10)*$AG$10,2))),"",IF($AF16="","",ROUND(($AF16/$AF$10)*$AG$10,2))) -> 100 | AH16: =IF($AG16="","",ROUND($AG16*$AH$10,2)) -> 20 | AI16: =IF(ISERROR(IF($AF16="","",ROUND(SUM($R16,$AE16,$AH16),2))),"",IF($AF16="","",ROUND(SUM($R16,$AE16,$AH16),2))) -> 96.07 | AJ16: =IF(ISERROR(IF($AF16="","",VLOOKUP(AI16,TRANSMUTATION_TABLE,4,TRUE))),"",IF($AF16="","",VLOOKUP(AI16,TRANSMUTATION_TABLE,4,TRUE))) -> 97
A17: 6 | B17: ='INPUT DATA'!B17 -> 6.Napuran, Thom Brenden Martecio | F17: 8 | G17: 10 | H17: 19 | I17: 5 | J17: 10 | K17: 14 | L17: 6 | M17: 15 | N17: 10 | O17: 20 | P17: =IF(COUNT($F17:$O17)=0,"",SUM($F17:$O17)) -> 117 | Q17: =IF(ISERROR(IF($P17="","",ROUND(($P17/$P$10)*$Q$10,2))),"",IF($P17="","",ROUND(($P17/$P$10)*$Q$10,2))) -> 83.57 | R17: =IF($Q17="","",ROUND($Q17*$R$10,2)) -> 25.07 | S17: 20 | T17: 10 | U17: 8 | V17: 20 | W17: 20 | X17: 20 | AC17: =IF(COUNT($S17:$AB17)=0,"",SUM($S17:$AB17)) -> 98 | AD17: =IF(ISERROR(IF($AC17="","",ROUND(($AC17/$AC$10)*$AD$10,2))),"",IF($AC17="","",ROUND(($AC17/$AC$10)*$AD$10,2))) -> 98 | AE17: =IF($AD17="","",ROUND($AD17*$AE$10,2)) -> 49 | AF17: 24 | AG17: =IF(ISERROR(IF($AF17="","",ROUND(($AF17/$AF$10)*$AG$10,2))),"",IF($AF17="","",ROUND(($AF17/$AF$10)*$AG$10,2))) -> 96 | AH17: =IF($AG17="","",ROUND($AG17*$AH$10,2)) -> 19.2 | AI17: =IF(ISERROR(IF($AF17="","",ROUND(SUM($R17,$AE17,$AH17),2))),"",IF($AF17="","",ROUND(SUM($R17,$AE17,$AH17),2))) -> 93.27 | AJ17: =IF(ISERROR(IF($AF17="","",VLOOKUP(AI17,TRANSMUTATION_TABLE,4,TRUE))),"",IF($AF17="","",VLOOKUP(AI17,TRANSMUTATION_TABLE,4,TRUE))) -> 95
A18: 7 | B18: ='INPUT DATA'!B18 -> 7.Rosinas, Nathaniel John | F18: 9 | G18: 7 | H18: 18 | I18: 15 | J18: 6 | K18: 14 | L18: 4 | M18: 16 | N18: 7 | O18: 16 | P18: =IF(COUNT($F18:$O18)=0,"",SUM($F18:$O18)) -> 112 | Q18: =IF(ISERROR(IF($P18="","",ROUND(($P18/$P$10)*$Q$10,2))),"",IF($P18="","",ROUND(($P18/$P$10)*$Q$10,2))) -> 80 | R18: =IF($Q18="","",ROUND($Q18*$R$10,2)) -> 24 | S18: 15 | T18: 10 | U18: 8 | V18: 20 | W18: 15 | X18: 20 | AC18: =IF(COUNT($S18:$AB18)=0,"",SUM($S18:$AB18)) -> 88 | AD18: =IF(ISERROR(IF($AC18="","",ROUND(($AC18/$AC$10)*$AD$10,2))),"",IF($AC18="","",ROUND(($AC18/$AC$10)*$AD$10,2))) -> 88 | AE18: =IF($AD18="","",ROUND($AD18*$AE$10,2)) -> 44 | AF18: 21 | AG18: =IF(ISERROR(IF($AF18="","",ROUND(($AF18/$AF$10)*$AG$10,2))),"",IF($AF18="","",ROUND(($AF18/$AF$10)*$AG$10,2))) -> 84 | AH18: =IF($AG18="","",ROUND($AG18*$AH$10,2)) -> 16.8 | AI18: =IF(ISERROR(IF($AF18="","",ROUND(SUM($R18,$AE18,$AH18),2))),"",IF($AF18="","",ROUND(SUM($R18,$AE18,$AH18),2))) -> 84.8 | AJ18: =IF(ISERROR(IF($AF18="","",VLOOKUP(AI18,TRANSMUTATION_TABLE,4,TRUE))),"",IF($AF18="","",VLOOKUP(AI18,TRANSMUTATION_TABLE,4,TRUE))) -> 90
A19: 8 | B19: ='INPUT DATA'!B19 -> 8.Salazar, Ulrich Gabrielle Asaytona | D19: 0 | F19: 8 | G19: 10 | H19: 20 | I19: 15 | J19: 9 | K19: 15 | L19: 9 | M19: 18 | N19: 10 | O19: 20 | P19: =IF(COUNT($F19:$O19)=0,"",SUM($F19:$O19)) -> 134 | Q19: =IF(ISERROR(IF($P19="","",ROUND(($P19/$P$10)*$Q$10,2))),"",IF($P19="","",ROUND(($P19/$P$10)*$Q$10,2))) -> 95.71 | R19: =IF($Q19="","",ROUND($Q19*$R$10,2)) -> 28.71 | S19: 20 | T19: 10 | U19: 8 | V19: 20 | W19: 20 | X19: 20 | AC19: =IF(COUNT($S19:$AB19)=0,"",SUM($S19:$AB19)) -> 98 | AD19: =IF(ISERROR(IF($AC19="","",ROUND(($AC19/$AC$10)*$AD$10,2))),"",IF($AC19="","",ROUND(($AC19/$AC$10)*$AD$10,2))) -> 98 | AE19: =IF($AD19="","",ROUND($AD19*$AE$10,2)) -> 49 | AF19: 25 | AG19: =IF(ISERROR(IF($AF19="","",ROUND(($AF19/$AF$10)*$AG$10,2))),"",IF($AF19="","",ROUND(($AF19/$AF$10)*$AG$10,2))) -> 100 | AH19: =IF($AG19="","",ROUND($AG19*$AH$10,2)) -> 20 | AI19: =IF(ISERROR(IF($AF19="","",ROUND(SUM($R19,$AE19,$AH19),2))),"",IF($AF19="","",ROUND(SUM($R19,$AE19,$AH19),2))) -> 97.71 | AJ19: =IF(ISERROR(IF($AF19="","",VLOOKUP(AI19,TRANSMUTATION_TABLE,4,TRUE))),"",IF($AF19="","",VLOOKUP(AI19,TRANSMUTATION_TABLE,4,TRUE))) -> 98
A20: 9 | B20: ='INPUT DATA'!B20 -> 9.Santos, Sean Daniel Diopines | F20: 10 | G20: 9 | H20: 18 | I20: 10 | J20: 10 | K20: 15 | L20: 9 | M20: 19 | N20: 10 | O20: 18 | P20: =IF(COUNT($F20:$O20)=0,"",SUM($F20:$O20)) -> 128 | Q20: =IF(ISERROR(IF($P20="","",ROUND(($P20/$P$10)*$Q$10,2))),"",IF($P20="","",ROUND(($P20/$P$10)*$Q$10,2))) -> 91.43 | R20: =IF($Q20="","",ROUND($Q20*$R$10,2)) -> 27.43 | S20: 18 | T20: 10 | U20: 8 | V20: 20 | W20: 15 | X20: 20 | AC20: =IF(COUNT($S20:$AB20)=0,"",SUM($S20:$AB20)) -> 91 | AD20: =IF(ISERROR(IF($AC20="","",ROUND(($AC20/$AC$10)*$AD$10,2))),"",IF($AC20="","",ROUND(($AC20/$AC$10)*$AD$10,2))) -> 91 | AE20: =IF($AD20="","",ROUND($AD20*$AE$10,2)) -> 45.5 | AF20: 25 | AG20: =IF(ISERROR(IF($AF20="","",ROUND(($AF20/$AF$10)*$AG$10,2))),"",IF($AF20="","",ROUND(($AF20/$AF$10)*$AG$10,2))) -> 100 | AH20: =IF($AG20="","",ROUND($AG20*$AH$10,2)) -> 20 | AI20: =IF(ISERROR(IF($AF20="","",ROUND(SUM($R20,$AE20,$AH20),2))),"",IF($AF20="","",ROUND(SUM($R20,$AE20,$AH20),2))) -> 92.93 | AJ20: =IF(ISERROR(IF($AF20="","",VLOOKUP(AI20,TRANSMUTATION_TABLE,4,TRUE))),"",IF($AF20="","",VLOOKUP(AI20,TRANSMUTATION_TABLE,4,TRUE))) -> 95
A21: 10 | B21: ='INPUT DATA'!B21 -> 10.Soriano, Zegen Khaleb C. | F21: 9 | G21: 4 | H21: 15 | I21: 15 | J21: 10 | K21: 9 | L21: 6 | M21: 18 | N21: 6 | O21: 16 | P21: =IF(COUNT($F21:$O21)=0,"",SUM($F21:$O21)) -> 108 | Q21: =IF(ISERROR(IF($P21="","",ROUND(($P21/$P$10)*$Q$10,2))),"",IF($P21="","",ROUND(($P21/$P$10)*$Q$10,2))) -> 77.14 | R21: =IF($Q21="","",ROUND($Q21*$R$10,2)) -> 23.14 | S21: 18 | T21: 10 | U21: 8 | V21: 20 | W21: 15 | X21: 20 | AC21: =IF(COUNT($S21:$AB21)=0,"",SUM($S21:$AB21)) -> 91 | AD21: =IF(ISERROR(IF($AC21="","",ROUND(($AC21/$AC$10)*$AD$10,2))),"",IF($AC21="","",ROUND(($AC21/$AC$10)*$AD$10,2))) -> 91 | AE21: =IF($AD21="","",ROUND($AD21*$AE$10,2)) -> 45.5 | AF21: 21 | AG21: =IF(ISERROR(IF($AF21="","",ROUND(($AF21/$AF$10)*$AG$10,2))),"",IF($AF21="","",ROUND(($AF21/$AF$10)*$AG$10,2))) -> 84 | AH21: =IF($AG21="","",ROUND($AG21*$AH$10,2)) -> 16.8 | AI21: =IF(ISERROR(IF($AF21="","",ROUND(SUM($R21,$AE21,$AH21),2))),"",IF($AF21="","",ROUND(SUM($R21,$AE21,$AH21),2))) -> 85.44 | AJ21: =IF(ISERROR(IF($AF21="","",VLOOKUP(AI21,TRANSMUTATION_TABLE,4,TRUE))),"",IF($AF21="","",VLOOKUP(AI21,TRANSMUTATION_TABLE,4,TRUE))) -> 90
A22: 11 | B22: ='INPUT DATA'!B22 -> 0 | D22: 0 | P22: =IF(COUNT($F22:$O22)=0,"",SUM($F22:$O22)) | Q22: =IF(ISERROR(IF($P22="","",ROUND(($P22/$P$10)*$Q$10,2))),"",IF($P22="","",ROUND(($P22/$P$10)*$Q$10,2))) | R22: =IF($Q22="","",ROUND($Q22*$R$10,2)) | AC22: =IF(COUNT($S22:$AB22)=0,"",SUM($S22:$AB22)) | AD22: =IF(ISERROR(IF($AC22="","",ROUND(($AC22/$AC$10)*$AD$10,2))),"",IF($AC22="","",ROUND(($AC22/$AC$10)*$AD$10,2))) | AE22: =IF($AD22="","",ROUND($AD22*$AE$10,2)) | AG22: =IF(ISERROR(IF($AF22="","",ROUND(($AF22/$AF$10)*$AG$10,2))),"",IF($AF22="","",ROUND(($AF22/$AF$10)*$AG$10,2))) | AH22: =IF($AG22="","",ROUND($AG22*$AH$10,2)) | AI22: =IF(ISERROR(IF($AF22="","",ROUND(SUM($R22,$AE22,$AH22),2))),"",IF($AF22="","",ROUND(SUM($R22,$AE22,$AH22),2))) | AJ22: =IF(ISERROR(IF($AF22="","",VLOOKUP(AI22,TRANSMUTATION_TABLE,4,TRUE))),"",IF($AF22="","",VLOOKUP(AI22,TRANSMUTATION_TABLE,4,TRUE)))
A23: 12 | B23: ='INPUT DATA'!B23 -> 0 | P23: =IF(COUNT($F23:$O23)=0,"",SUM($F23:$O23)) | Q23: =IF(ISERROR(IF($P23="","",ROUND(($P23/$P$10)*$Q$10,2))),"",IF($P23="","",ROUND(($P23/$P$10)*$Q$10,2))) | R23: =IF($Q23="","",ROUND($Q23*$R$10,2)) | AC23: =IF(COUNT($S23:$AB23)=0,"",SUM($S23:$AB23)) | AD23: =IF(ISERROR(IF($AC23="","",ROUND(($AC23/$AC$10)*$AD$10,2))),"",IF($AC23="","",ROUND(($AC23/$AC$10)*$AD$10,2))) | AE23: =IF($AD23="","",ROUND($AD23*$AE$10,2)) | AG23: =IF(ISERROR(IF($AF23="","",ROUND(($AF23/$AF$10)*$AG$10,2))),"",IF($AF23="","",ROUND(($AF23/$AF$10)*$AG$10,2))) | AH23: =IF($AG23="","",ROUND($AG23*$AH$10,2)) | AI23: =IF(ISERROR(IF($AF23="","",ROUND(SUM($R23,$AE23,$AH23),2))),"",IF($AF23="","",ROUND(SUM($R23,$AE23,$AH23),2))) | AJ23: =IF(ISERROR(IF($AF23="","",VLOOKUP(AI23,TRANSMUTATION_TABLE,4,TRUE))),"",IF($AF23="","",VLOOKUP(AI23,TRANSMUTATION_TABLE,4,TRUE)))
A24: 13 | B24: ='INPUT DATA'!B24 -> FEMALE | P24: =IF(COUNT($F24:$O24)=0,"",SUM($F24:$O24)) | Q24: =IF(ISERROR(IF($P24="","",ROUND(($P24/$P$10)*$Q$10,2))),"",IF($P24="","",ROUND(($P24/$P$10)*$Q$10,2))) | R24: =IF($Q24="","",ROUND($Q24*$R$10,2)) | AC24: =IF(COUNT($S24:$AB24)=0,"",SUM($S24:$AB24)) | AD24: =IF(ISERROR(IF($AC24="","",ROUND(($AC24/$AC$10)*$AD$10,2))),"",IF($AC24="","",ROUND(($AC24/$AC$10)*$AD$10,2))) | AE24: =IF($AD24="","",ROUND($AD24*$AE$10,2)) | AG24: =IF(ISERROR(IF($AF24="","",ROUND(($AF24/$AF$10)*$AG$10,2))),"",IF($AF24="","",ROUND(($AF24/$AF$10)*$AG$10,2))) | AH24: =IF($AG24="","",ROUND($AG24*$AH$10,2)) | AI24: =IF(ISERROR(IF($AF24="","",ROUND(SUM($R24,$AE24,$AH24),2))),"",IF($AF24="","",ROUND(SUM($R24,$AE24,$AH24),2))) | AJ24: =IF(ISERROR(IF($AF24="","",VLOOKUP(AI24,TRANSMUTATION_TABLE,4,TRUE))),"",IF($AF24="","",VLOOKUP(AI24,TRANSMUTATION_TABLE,4,TRUE)))
A25: 14 | B25: ='INPUT DATA'!B25 -> 1. Algabre, Sophia Ysabelle Dagle | F25: 8 | G25: 9 | H25: 12 | I25: 8 | J25: 8 | K25: 9 | L25: 5 | M25: 13 | N25: 6 | O25: 13 | P25: =IF(COUNT($F25:$O25)=0,"",SUM($F25:$O25)) -> 91 | Q25: =IF(ISERROR(IF($P25="","",ROUND(($P25/$P$10)*$Q$10,2))),"",IF($P25="","",ROUND(($P25/$P$10)*$Q$10,2))) -> 65 | R25: =IF($Q25="","",ROUND($Q25*$R$10,2)) -> 19.5 | S25: 15 | T25: 10 | U25: 9 | V25: 10 | W25: 15 | X25: 20 | AC25: =IF(COUNT($S25:$AB25)=0,"",SUM($S25:$AB25)) -> 79 | AD25: =IF(ISERROR(IF($AC25="","",ROUND(($AC25/$AC$10)*$AD$10,2))),"",IF($AC25="","",ROUND(($AC25/$AC$10)*$AD$10,2))) -> 79 | AE25: =IF($AD25="","",ROUND($AD25*$AE$10,2)) -> 39.5 | AF25: 22 | AG25: =IF(ISERROR(IF($AF25="","",ROUND(($AF25/$AF$10)*$AG$10,2))),"",IF($AF25="","",ROUND(($AF25/$AF$10)*$AG$10,2))) -> 88 | AH25: =IF($AG25="","",ROUND($AG25*$AH$10,2)) -> 17.6 | AI25: =IF(ISERROR(IF($AF25="","",ROUND(SUM($R25,$AE25,$AH25),2))),"",IF($AF25="","",ROUND(SUM($R25,$AE25,$AH25),2))) -> 76.6 | AJ25: =IF(ISERROR(IF($AF25="","",VLOOKUP(AI25,TRANSMUTATION_TABLE,4,TRUE))),"",IF($AF25="","",VLOOKUP(AI25,TRANSMUTATION_TABLE,4,TRUE))) -> 85
A26: 15 | B26: ='INPUT DATA'!B26 -> 2. Bade, Myel Ellyre, Bernales | F26: 8 | G26: 9 | H26: 10 | I26: 8 | J26: 7 | K26: 8 | L26: 8 | M26: 15 | N26: 5 | O26: 13 | P26: =IF(COUNT($F26:$O26)=0,"",SUM($F26:$O26)) -> 91 | Q26: =IF(ISERROR(IF($P26="","",ROUND(($P26/$P$10)*$Q$10,2))),"",IF($P26="","",ROUND(($P26/$P$10)*$Q$10,2))) -> 65 | R26: =IF($Q26="","",ROUND($Q26*$R$10,2)) -> 19.5 | S26: 18 | T26: 7 | U26: 10 | V26: 20 | W26: 20 | X26: 20 | AC26: =IF(COUNT($S26:$AB26)=0,"",SUM($S26:$AB26)) -> 95 | AD26: =IF(ISERROR(IF($AC26="","",ROUND(($AC26/$AC$10)*$AD$10,2))),"",IF($AC26="","",ROUND(($AC26/$AC$10)*$AD$10,2))) -> 95 | AE26: =IF($AD26="","",ROUND($AD26*$AE$10,2)) -> 47.5 | AF26: 21 | AG26: =IF(ISERROR(IF($AF26="","",ROUND(($AF26/$AF$10)*$AG$10,2))),"",IF($AF26="","",ROUND(($AF26/$AF$10)*$AG$10,2))) -> 84 | AH26: =IF($AG26="","",ROUND($AG26*$AH$10,2)) -> 16.8 | AI26: =IF(ISERROR(IF($AF26="","",ROUND(SUM($R26,$AE26,$AH26),2))),"",IF($AF26="","",ROUND(SUM($R26,$AE26,$AH26),2))) -> 83.8 | AJ26: =IF(ISERROR(IF($AF26="","",VLOOKUP(AI26,TRANSMUTATION_TABLE,4,TRUE))),"",IF($AF26="","",VLOOKUP(AI26,TRANSMUTATION_TABLE,4,TRUE))) -> 89
A27: 16 | B27: ='INPUT DATA'!B27 -> 3. Bangcal, Colynn Dela Rosa | F27: 8 | G27: 5 | H27: 19 | I27: 10 | J27: 10 | K27: 11 | L27: 10 | M27: 17 | N27: 9 | O27: 17 | P27: =IF(COUNT($F27:$O27)=0,"",SUM($F27:$O27)) -> 116 | Q27: =IF(ISERROR(IF($P27="","",ROUND(($P27/$P$10)*$Q$10,2))),"",IF($P27="","",ROUND(($P27/$P$10)*$Q$10,2))) -> 82.86 | R27: =IF($Q27="","",ROUND($Q27*$R$10,2)) -> 24.86 | S27: 18 | T27: 10 | U27: 9 | V27: 15 | W27: 16 | X27: 20 | AC27: =IF(COUNT($S27:$AB27)=0,"",SUM($S27:$AB27)) -> 88 | AD27: =IF(ISERROR(IF($AC27="","",ROUND(($AC27/$AC$10)*$AD$10,2))),"",IF($AC27="","",ROUND(($AC27/$AC$10)*$AD$10,2))) -> 88 | AE27: =IF($AD27="","",ROUND($AD27*$AE$10,2)) -> 44 | AF27: 23 | AG27: =IF(ISERROR(IF($AF27="","",ROUND(($AF27/$AF$10)*$AG$10,2))),"",IF($AF27="","",ROUND(($AF27/$AF$10)*$AG$10,2))) -> 92 | AH27: =IF($AG27="","",ROUND($AG27*$AH$10,2)) -> 18.4 | AI27: =IF(ISERROR(IF($AF27="","",ROUND(SUM($R27,$AE27,$AH27),2))),"",IF($AF27="","",ROUND(SUM($R27,$AE27,$AH27),2))) -> 87.26 | AJ27: =IF(ISERROR(IF($AF27="","",VLOOKUP(AI27,TRANSMUTATION_TABLE,4,TRUE))),"",IF($AF27="","",VLOOKUP(AI27,TRANSMUTATION_TABLE,4,TRUE))) -> 92
A28: 17 | B28: ='INPUT DATA'!B28 -> 4. Caballero, Amber Yasha, Omambac | F28: 6 | G28: 5 | H28: 20 | I28: 15 | J28: 7 | K28: 12 | L28: 4 | M28: 15 | N28: 9 | O28: 18 | P28: =IF(COUNT($F28:$O28)=0,"",SUM($F28:$O28)) -> 111 | Q28: =IF(ISERROR(IF($P28="","",ROUND(($P28/$P$10)*$Q$10,2))),"",IF($P28="","",ROUND(($P28/$P$10)*$Q$10,2))) -> 79.29 | R28: =IF($Q28="","",ROUND($Q28*$R$10,2)) -> 23.79 | S28: 16 | T28: 10 | U28: 9 | V28: 20 | W28: 15 | X28: 20 | AC28: =IF(COUNT($S28:$AB28)=0,"",SUM($S28:$AB28)) -> 90 | AD28: =IF(ISERROR(IF($AC28="","",ROUND(($AC28/$AC$10)*$AD$10,2))),"",IF($AC28="","",ROUND(($AC28/$AC$10)*$AD$10,2))) -> 90 | AE28: =IF($AD28="","",ROUND($AD28*$AE$10,2)) -> 45 | AF28: 24 | AG28: =IF(ISERROR(IF($AF28="","",ROUND(($AF28/$AF$10)*$AG$10,2))),"",IF($AF28="","",ROUND(($AF28/$AF$10)*$AG$10,2))) -> 96 | AH28: =IF($AG28="","",ROUND($AG28*$AH$10,2)) -> 19.2 | AI28: =IF(ISERROR(IF($AF28="","",ROUND(SUM($R28,$AE28,$AH28),2))),"",IF($AF28="","",ROUND(SUM($R28,$AE28,$AH28),2))) -> 87.99 | AJ28: =IF(ISERROR(IF($AF28="","",VLOOKUP(AI28,TRANSMUTATION_TABLE,4,TRUE))),"",IF($AF28="","",VLOOKUP(AI28,TRANSMUTATION_TABLE,4,TRUE))) -> 92
A29: 18 | B29: ='INPUT DATA'!B29 -> 5.Calilan, Olivia Mula | F29: 5 | G29: 8 | H29: 19 | I29: 10 | J29: 8 | K29: 12 | L29: 10 | M29: 14 | N29: 9 | O29: 19 | P29: =IF(COUNT($F29:$O29)=0,"",SUM($F29:$O29)) -> 114 | Q29: =IF(ISERROR(IF($P29="","",ROUND(($P29/$P$10)*$Q$10,2))),"",IF($P29="","",ROUND(($P29/$P$10)*$Q$10,2))) -> 81.43 | R29: =IF($Q29="","",ROUND($Q29*$R$10,2)) -> 24.43 | S29: 17 | T29: 10 | U29: 8 | V29: 15 | W29: 15 | X29: 20 | AC29: =IF(COUNT($S29:$AB29)=0,"",SUM($S29:$AB29)) -> 85 | AD29: =IF(ISERROR(IF($AC29="","",ROUND(($AC29/$AC$10)*$AD$10,2))),"",IF($AC29="","",ROUND(($AC29/$AC$10)*$AD$10,2))) -> 85 | AE29: =IF($AD29="","",ROUND($AD29*$AE$10,2)) -> 42.5 | AF29: 22 | AG29: =IF(ISERROR(IF($AF29="","",ROUND(($AF29/$AF$10)*$AG$10,2))),"",IF($AF29="","",ROUND(($AF29/$AF$10)*$AG$10,2))) -> 88 | AH29: =IF($AG29="","",ROUND($AG29*$AH$10,2)) -> 17.6 | AI29: =IF(ISERROR(IF($AF29="","",ROUND(SUM($R29,$AE29,$AH29),2))),"",IF($AF29="","",ROUND(SUM($R29,$AE29,$AH29),2))) -> 84.53 | AJ29: =IF(ISERROR(IF($AF29="","",VLOOKUP(AI29,TRANSMUTATION_TABLE,4,TRUE))),"",IF($AF29="","",VLOOKUP(AI29,TRANSMUTATION_TABLE,4,TRUE))) -> 90
A30: 19 | B30: ='INPUT DATA'!B30 -> 6.Facundo, Aleena | F30: 9 | G30: 5 | H30: 15 | I30: 10 | J30: 3 | K30: 10 | L30: 8 | M30: 5 | N30: 5 | O30: 13 | P30: =IF(COUNT($F30:$O30)=0,"",SUM($F30:$O30)) -> 83 | Q30: =IF(ISERROR(IF($P30="","",ROUND(($P30/$P$10)*$Q$10,2))),"",IF($P30="","",ROUND(($P30/$P$10)*$Q$10,2))) -> 59.29 | R30: =IF($Q30="","",ROUND($Q30*$R$10,2)) -> 17.79 | S30: 16 | T30: 10 | U30: 7 | V30: 20 | W30: 15 | X30: 20 | AC30: =IF(COUNT($S30:$AB30)=0,"",SUM($S30:$AB30)) -> 88 | AD30: =IF(ISERROR(IF($AC30="","",ROUND(($AC30/$AC$10)*$AD$10,2))),"",IF($AC30="","",ROUND(($AC30/$AC$10)*$AD$10,2))) -> 88 | AE30: =IF($AD30="","",ROUND($AD30*$AE$10,2)) -> 44 | AF30: 18 | AG30: =IF(ISERROR(IF($AF30="","",ROUND(($AF30/$AF$10)*$AG$10,2))),"",IF($AF30="","",ROUND(($AF30/$AF$10)*$AG$10,2))) -> 72 | AH30: =IF($AG30="","",ROUND($AG30*$AH$10,2)) -> 14.4 | AI30: =IF(ISERROR(IF($AF30="","",ROUND(SUM($R30,$AE30,$AH30),2))),"",IF($AF30="","",ROUND(SUM($R30,$AE30,$AH30),2))) -> 76.19 | AJ30: =IF(ISERROR(IF($AF30="","",VLOOKUP(AI30,TRANSMUTATION_TABLE,4,TRUE))),"",IF($AF30="","",VLOOKUP(AI30,TRANSMUTATION_TABLE,4,TRUE))) -> 85
A31: 20 | B31: ='INPUT DATA'!B31 -> 7.Ferriols, Francine Faith | F31: 9 | G31: 8 | H31: 18 | I31: 12 | J31: 10 | K31: 11 | L31: 5 | M31: 15 | N31: 6 | O31: 12 | P31: =IF(COUNT($F31:$O31)=0,"",SUM($F31:$O31)) -> 106 | Q31: =IF(ISERROR(IF($P31="","",ROUND(($P31/$P$10)*$Q$10,2))),"",IF($P31="","",ROUND(($P31/$P$10)*$Q$10,2))) -> 75.71 | R31: =IF($Q31="","",ROUND($Q31*$R$10,2)) -> 22.71 | S31: 17 | T31: 10 | U31: 10 | V31: 10 | W31: 15 | X31: 20 | AC31: =IF(COUNT($S31:$AB31)=0,"",SUM($S31:$AB31)) -> 82 | AD31: =IF(ISERROR(IF($AC31="","",ROUND(($AC31/$AC$10)*$AD$10,2))),"",IF($AC31="","",ROUND(($AC31/$AC$10)*$AD$10,2))) -> 82 | AE31: =IF($AD31="","",ROUND($AD31*$AE$10,2)) -> 41 | AF31: 19 | AG31: =IF(ISERROR(IF($AF31="","",ROUND(($AF31/$AF$10)*$AG$10,2))),"",IF($AF31="","",ROUND(($AF31/$AF$10)*$AG$10,2))) -> 76 | AH31: =IF($AG31="","",ROUND($AG31*$AH$10,2)) -> 15.2 | AI31: =IF(ISERROR(IF($AF31="","",ROUND(SUM($R31,$AE31,$AH31),2))),"",IF($AF31="","",ROUND(SUM($R31,$AE31,$AH31),2))) -> 78.91 | AJ31: =IF(ISERROR(IF($AF31="","",VLOOKUP(AI31,TRANSMUTATION_TABLE,4,TRUE))),"",IF($AF31="","",VLOOKUP(AI31,TRANSMUTATION_TABLE,4,TRUE))) -> 86
A32: 21 | B32: ='INPUT DATA'!B32 -> 8.Tagalog, Eysa Duron | F32: 10 | G32: 10 | H32: 15 | I32: 15 | J32: 10 | K32: 13 | L32: 8 | M32: 17 | N32: 9 | O32: 20 | P32: =IF(COUNT($F32:$O32)=0,"",SUM($F32:$O32)) -> 127 | Q32: =IF(ISERROR(IF($P32="","",ROUND(($P32/$P$10)*$Q$10,2))),"",IF($P32="","",ROUND(($P32/$P$10)*$Q$10,2))) -> 90.71 | R32: =IF($Q32="","",ROUND($Q32*$R$10,2)) -> 27.21 | S32: 18 | T32: 10 | U32: 10 | V32: 18 | W32: 19 | X32: 20 | AC32: =IF(COUNT($S32:$AB32)=0,"",SUM($S32:$AB32)) -> 95 | AD32: =IF(ISERROR(IF($AC32="","",ROUND(($AC32/$AC$10)*$AD$10,2))),"",IF($AC32="","",ROUND(($AC32/$AC$10)*$AD$10,2))) -> 95 | AE32: =IF($AD32="","",ROUND($AD32*$AE$10,2)) -> 47.5 | AF32: 25 | AG32: =IF(ISERROR(IF($AF32="","",ROUND(($AF32/$AF$10)*$AG$10,2))),"",IF($AF32="","",ROUND(($AF32/$AF$10)*$AG$10,2))) -> 100 | AH32: =IF($AG32="","",ROUND($AG32*$AH$10,2)) -> 20 | AI32: =IF(ISERROR(IF($AF32="","",ROUND(SUM($R32,$AE32,$AH32),2))),"",IF($AF32="","",ROUND(SUM($R32,$AE32,$AH32),2))) -> 94.71 | AJ32: =IF(ISERROR(IF($AF32="","",VLOOKUP(AI32,TRANSMUTATION_TABLE,4,TRUE))),"",IF($AF32="","",VLOOKUP(AI32,TRANSMUTATION_TABLE,4,TRUE))) -> 96
A33: 22 | B33: ='INPUT DATA'!B33 -> 0 | P33: =IF(COUNT($F33:$O33)=0,"",SUM($F33:$O33)) | Q33: =IF(ISERROR(IF($P33="","",ROUND(($P33/$P$10)*$Q$10,2))),"",IF($P33="","",ROUND(($P33/$P$10)*$Q$10,2))) | R33: =IF($Q33="","",ROUND($Q33*$R$10,2)) | AC33: =IF(COUNT($S33:$AB33)=0,"",SUM($S33:$AB33)) | AD33: =IF(ISERROR(IF($AC33="","",ROUND(($AC33/$AC$10)*$AD$10,2))),"",IF($AC33="","",ROUND(($AC33/$AC$10)*$AD$10,2))) | AE33: =IF($AD33="","",ROUND($AD33*$AE$10,2)) | AG33: =IF(ISERROR(IF($AF33="","",ROUND(($AF33/$AF$10)*$AG$10,2))),"",IF($AF33="","",ROUND(($AF33/$AF$10)*$AG$10,2))) | AH33: =IF($AG33="","",ROUND($AG33*$AH$10,2)) | AI33: =IF(ISERROR(IF($AF33="","",ROUND(SUM($R33,$AE33,$AH33),2))),"",IF($AF33="","",ROUND(SUM($R33,$AE33,$AH33),2))) | AJ33: =IF(ISERROR(IF($AF33="","",VLOOKUP(AI33,TRANSMUTATION_TABLE,4,TRUE))),"",IF($AF33="","",VLOOKUP(AI33,TRANSMUTATION_TABLE,4,TRUE)))
A34: 23 | B34: ='INPUT DATA'!B34 -> 0 | P34: =IF(COUNT($F34:$O34)=0,"",SUM($F34:$O34)) | Q34: =IF(ISERROR(IF($P34="","",ROUND(($P34/$P$10)*$Q$10,2))),"",IF($P34="","",ROUND(($P34/$P$10)*$Q$10,2))) | R34: =IF($Q34="","",ROUND($Q34*$R$10,2)) | AC34: =IF(COUNT($S34:$AB34)=0,"",SUM($S34:$AB34)) | AD34: =IF(ISERROR(IF($AC34="","",ROUND(($AC34/$AC$10)*$AD$10,2))),"",IF($AC34="","",ROUND(($AC34/$AC$10)*$AD$10,2))) | AE34: =IF($AD34="","",ROUND($AD34*$AE$10,2)) | AG34: =IF(ISERROR(IF($AF34="","",ROUND(($AF34/$AF$10)*$AG$10,2))),"",IF($AF34="","",ROUND(($AF34/$AF$10)*$AG$10,2))) | AH34: =IF($AG34="","",ROUND($AG34*$AH$10,2)) | AI34: =IF(ISERROR(IF($AF34="","",ROUND(SUM($R34,$AE34,$AH34),2))),"",IF($AF34="","",ROUND(SUM($R34,$AE34,$AH34),2))) | AJ34: =IF(ISERROR(IF($AF34="","",VLOOKUP(AI34,TRANSMUTATION_TABLE,4,TRUE))),"",IF($AF34="","",VLOOKUP(AI34,TRANSMUTATION_TABLE,4,TRUE)))
A35: 24 | B35: ='INPUT DATA'!B35 -> 0 | P35: =IF(COUNT($F35:$O35)=0,"",SUM($F35:$O35)) | Q35: =IF(ISERROR(IF($P35="","",ROUND(($P35/$P$10)*$Q$10,2))),"",IF($P35="","",ROUND(($P35/$P$10)*$Q$10,2))) | R35: =IF($Q35="","",ROUND($Q35*$R$10,2)) | AC35: =IF(COUNT($S35:$AB35)=0,"",SUM($S35:$AB35)) | AD35: =IF(ISERROR(IF($AC35="","",ROUND(($AC35/$AC$10)*$AD$10,2))),"",IF($AC35="","",ROUND(($AC35/$AC$10)*$AD$10,2))) | AE35: =IF($AD35="","",ROUND($AD35*$AE$10,2)) | AG35: =IF(ISERROR(IF($AF35="","",ROUND(($AF35/$AF$10)*$AG$10,2))),"",IF($AF35="","",ROUND(($AF35/$AF$10)*$AG$10,2))) | AH35: =IF($AG35="","",ROUND($AG35*$AH$10,2)) | AI35: =IF(ISERROR(IF($AF35="","",ROUND(SUM($R35,$AE35,$AH35),2))),"",IF($AF35="","",ROUND(SUM($R35,$AE35,$AH35),2))) | AJ35: =IF(ISERROR(IF($AF35="","",VLOOKUP(AI35,TRANSMUTATION_TABLE,4,TRUE))),"",IF($AF35="","",VLOOKUP(AI35,TRANSMUTATION_TABLE,4,TRUE)))
A36: 25 | B36: ='INPUT DATA'!B36 -> 0 | P36: =IF(COUNT($F36:$O36)=0,"",SUM($F36:$O36)) | Q36: =IF(ISERROR(IF($P36="","",ROUND(($P36/$P$10)*$Q$10,2))),"",IF($P36="","",ROUND(($P36/$P$10)*$Q$10,2))) | R36: =IF($Q36="","",ROUND($Q36*$R$10,2)) | AC36: =IF(COUNT($S36:$AB36)=0,"",SUM($S36:$AB36)) | AD36: =IF(ISERROR(IF($AC36="","",ROUND(($AC36/$AC$10)*$AD$10,2))),"",IF($AC36="","",ROUND(($AC36/$AC$10)*$AD$10,2))) | AE36: =IF($AD36="","",ROUND($AD36*$AE$10,2)) | AG36: =IF(ISERROR(IF($AF36="","",ROUND(($AF36/$AF$10)*$AG$10,2))),"",IF($AF36="","",ROUND(($AF36/$AF$10)*$AG$10,2))) | AH36: =IF($AG36="","",ROUND($AG36*$AH$10,2)) | AI36: =IF(ISERROR(IF($AF36="","",ROUND(SUM($R36,$AE36,$AH36),2))),"",IF($AF36="","",ROUND(SUM($R36,$AE36,$AH36),2))) | AJ36: =IF(ISERROR(IF($AF36="","",VLOOKUP(AI36,TRANSMUTATION_TABLE,4,TRUE))),"",IF($AF36="","",VLOOKUP(AI36,TRANSMUTATION_TABLE,4,TRUE)))
A37: 26 | B37: ='INPUT DATA'!B37 -> 0 | P37: =IF(COUNT($F37:$O37)=0,"",SUM($F37:$O37)) | Q37: =IF(ISERROR(IF($P37="","",ROUND(($P37/$P$10)*$Q$10,2))),"",IF($P37="","",ROUND(($P37/$P$10)*$Q$10,2))) | R37: =IF($Q37="","",ROUND($Q37*$R$10,2)) | AC37: =IF(COUNT($S37:$AB37)=0,"",SUM($S37:$AB37)) | AD37: =IF(ISERROR(IF($AC37="","",ROUND(($AC37/$AC$10)*$AD$10,2))),"",IF($AC37="","",ROUND(($AC37/$AC$10)*$AD$10,2))) | AE37: =IF($AD37="","",ROUND($AD37*$AE$10,2)) | AG37: =IF(ISERROR(IF($AF37="","",ROUND(($AF37/$AF$10)*$AG$10,2))),"",IF($AF37="","",ROUND(($AF37/$AF$10)*$AG$10,2))) | AH37: =IF($AG37="","",ROUND($AG37*$AH$10,2)) | AI37: =IF(ISERROR(IF($AF37="","",ROUND(SUM($R37,$AE37,$AH37),2))),"",IF($AF37="","",ROUND(SUM($R37,$AE37,$AH37),2))) | AJ37: =IF(ISERROR(IF($AF37="","",VLOOKUP(AI37,TRANSMUTATION_TABLE,4,TRUE))),"",IF($AF37="","",VLOOKUP(AI37,TRANSMUTATION_TABLE,4,TRUE)))
A38: 27 | B38: ='INPUT DATA'!B38 -> 0 | P38: =IF(COUNT($F38:$O38)=0,"",SUM($F38:$O38)) | Q38: =IF(ISERROR(IF($P38="","",ROUND(($P38/$P$10)*$Q$10,2))),"",IF($P38="","",ROUND(($P38/$P$10)*$Q$10,2))) | R38: =IF($Q38="","",ROUND($Q38*$R$10,2)) | AC38: =IF(COUNT($S38:$AB38)=0,"",SUM($S38:$AB38)) | AD38: =IF(ISERROR(IF($AC38="","",ROUND(($AC38/$AC$10)*$AD$10,2))),"",IF($AC38="","",ROUND(($AC38/$AC$10)*$AD$10,2))) | AE38: =IF($AD38="","",ROUND($AD38*$AE$10,2)) | AG38: =IF(ISERROR(IF($AF38="","",ROUND(($AF38/$AF$10)*$AG$10,2))),"",IF($AF38="","",ROUND(($AF38/$AF$10)*$AG$10,2))) | AH38: =IF($AG38="","",ROUND($AG38*$AH$10,2)) | AI38: =IF(ISERROR(IF($AF38="","",ROUND(SUM($R38,$AE38,$AH38),2))),"",IF($AF38="","",ROUND(SUM($R38,$AE38,$AH38),2))) | AJ38: =IF(ISERROR(IF($AF38="","",VLOOKUP(AI38,TRANSMUTATION_TABLE,4,TRUE))),"",IF($AF38="","",VLOOKUP(AI38,TRANSMUTATION_TABLE,4,TRUE)))
A39: 28 | B39: ='INPUT DATA'!B39 -> 0 | P39: =IF(COUNT($F39:$O39)=0,"",SUM($F39:$O39)) | Q39: =IF(ISERROR(IF($P39="","",ROUND(($P39/$P$10)*$Q$10,2))),"",IF($P39="","",ROUND(($P39/$P$10)*$Q$10,2))) | R39: =IF($Q39="","",ROUND($Q39*$R$10,2)) | AC39: =IF(COUNT($S39:$AB39)=0,"",SUM($S39:$AB39)) | AD39: =IF(ISERROR(IF($AC39="","",ROUND(($AC39/$AC$10)*$AD$10,2))),"",IF($AC39="","",ROUND(($AC39/$AC$10)*$AD$10,2))) | AE39: =IF($AD39="","",ROUND($AD39*$AE$10,2)) | AG39: =IF(ISERROR(IF($AF39="","",ROUND(($AF39/$AF$10)*$AG$10,2))),"",IF($AF39="","",ROUND(($AF39/$AF$10)*$AG$10,2))) | AH39: =IF($AG39="","",ROUND($AG39*$AH$10,2)) | AI39: =IF(ISERROR(IF($AF39="","",ROUND(SUM($R39,$AE39,$AH39),2))),"",IF($AF39="","",ROUND(SUM($R39,$AE39,$AH39),2))) | AJ39: =IF(ISERROR(IF($AF39="","",VLOOKUP(AI39,TRANSMUTATION_TABLE,4,TRUE))),"",IF($AF39="","",VLOOKUP(AI39,TRANSMUTATION_TABLE,4,TRUE)))
A40: 29 | B40: ='INPUT DATA'!B40 -> 0 | P40: =IF(COUNT($F40:$O40)=0,"",SUM($F40:$O40)) | Q40: =IF(ISERROR(IF($P40="","",ROUND(($P40/$P$10)*$Q$10,2))),"",IF($P40="","",ROUND(($P40/$P$10)*$Q$10,2))) | R40: =IF($Q40="","",ROUND($Q40*$R$10,2)) | AC40: =IF(COUNT($S40:$AB40)=0,"",SUM($S40:$AB40)) | AD40: =IF(ISERROR(IF($AC40="","",ROUND(($AC40/$AC$10)*$AD$10,2))),"",IF($AC40="","",ROUND(($AC40/$AC$10)*$AD$10,2))) | AE40: =IF($AD40="","",ROUND($AD40*$AE$10,2)) | AG40: =IF(ISERROR(IF($AF40="","",ROUND(($AF40/$AF$10)*$AG$10,2))),"",IF($AF40="","",ROUND(($AF40/$AF$10)*$AG$10,2))) | AH40: =IF($AG40="","",ROUND($AG40*$AH$10,2)) | AI40: =IF(ISERROR(IF($AF40="","",ROUND(SUM($R40,$AE40,$AH40),2))),"",IF($AF40="","",ROUND(SUM($R40,$AE40,$AH40),2))) | AJ40: =IF(ISERROR(IF($AF40="","",VLOOKUP(AI40,TRANSMUTATION_TABLE,4,TRUE))),"",IF($AF40="","",VLOOKUP(AI40,TRANSMUTATION_TABLE,4,TRUE)))
A41: 30 | B41: ='INPUT DATA'!B41 -> 0 | P41: =IF(COUNT($F41:$O41)=0,"",SUM($F41:$O41)) | Q41: =IF(ISERROR(IF($P41="","",ROUND(($P41/$P$10)*$Q$10,2))),"",IF($P41="","",ROUND(($P41/$P$10)*$Q$10,2))) | R41: =IF($Q41="","",ROUND($Q41*$R$10,2)) | AC41: =IF(COUNT($S41:$AB41)=0,"",SUM($S41:$AB41)) | AD41: =IF(ISERROR(IF($AC41="","",ROUND(($AC41/$AC$10)*$AD$10,2))),"",IF($AC41="","",ROUND(($AC41/$AC$10)*$AD$10,2))) | AE41: =IF($AD41="","",ROUND($AD41*$AE$10,2)) | AG41: =IF(ISERROR(IF($AF41="","",ROUND(($AF41/$AF$10)*$AG$10,2))),"",IF($AF41="","",ROUND(($AF41/$AF$10)*$AG$10,2))) | AH41: =IF($AG41="","",ROUND($AG41*$AH$10,2)) | AI41: =IF(ISERROR(IF($AF41="","",ROUND(SUM($R41,$AE41,$AH41),2))),"",IF($AF41="","",ROUND(SUM($R41,$AE41,$AH41),2))) | AJ41: =IF(ISERROR(IF($AF41="","",VLOOKUP(AI41,TRANSMUTATION_TABLE,4,TRUE))),"",IF($AF41="","",VLOOKUP(AI41,TRANSMUTATION_TABLE,4,TRUE)))
A42: 31 | B42: ='INPUT DATA'!B42 -> 0 | P42: =IF(COUNT($F42:$O42)=0,"",SUM($F42:$O42)) | Q42: =IF(ISERROR(IF($P42="","",ROUND(($P42/$P$10)*$Q$10,2))),"",IF($P42="","",ROUND(($P42/$P$10)*$Q$10,2))) | R42: =IF($Q42="","",ROUND($Q42*$R$10,2)) | AC42: =IF(COUNT($S42:$AB42)=0,"",SUM($S42:$AB42)) | AD42: =IF(ISERROR(IF($AC42="","",ROUND(($AC42/$AC$10)*$AD$10,2))),"",IF($AC42="","",ROUND(($AC42/$AC$10)*$AD$10,2))) | AE42: =IF($AD42="","",ROUND($AD42*$AE$10,2)) | AG42: =IF(ISERROR(IF($AF42="","",ROUND(($AF42/$AF$10)*$AG$10,2))),"",IF($AF42="","",ROUND(($AF42/$AF$10)*$AG$10,2))) | AH42: =IF($AG42="","",ROUND($AG42*$AH$10,2)) | AI42: =IF(ISERROR(IF($AF42="","",ROUND(SUM($R42,$AE42,$AH42),2))),"",IF($AF42="","",ROUND(SUM($R42,$AE42,$AH42),2))) | AJ42: =IF(ISERROR(IF($AF42="","",VLOOKUP(AI42,TRANSMUTATION_TABLE,4,TRUE))),"",IF($AF42="","",VLOOKUP(AI42,TRANSMUTATION_TABLE,4,TRUE)))
...

Sheet FILIPINO
A1: Class Record
A3: (Pursuant to Deped Order 8 series of 2015)
C4: REGION | G4: ='INPUT DATA'!G4 -> 0 | L4: DIVISION | O4: ='INPUT DATA'!O4 -> 0 | T4: DISTRICT | X4: ='INPUT DATA'!X4 -> 0
B5: SCHOOL NAME | G5: Toril UCCP Learning Center Inc. | T5: SCHOOL ID | X5: ='INPUT DATA'!X5 -> 0 | AD5: SCHOOL YEAR | AG5: 2025-2026
A7: FIRST QUARTER | F7: GRADE & SECTION: | K7: 2-Jacob | Q7: TEACHER: | S7: Prinaniel A. Rosalita | AC7: SUBJECT: | AG7: Filipino
B8: LEARNERS' NAMES | F8: WRITTEN WORKS (30%) | S8: PERFORMANCE TASKS (50%) | AF8: QUARTERLY ASSESSMENT (20%) | AI8: Initial | AJ8: Quarterly
F9: July 23 2025 | G9: 45867 | H9: summative | I9: August 5 2025 | J9: August 6,2025 | K9: summative | L9: Prelim exam | M9: 45881 | N9: 45888 | O9: 45889 | P9: Total | Q9: PS | R9: WS | S9: Oral Recitation | T9: Attendance | U9: Group activity | V9: Pagsulat ng Pangungusap | W9: Tula | X9: Buwan ng wika | Y9: 7 | Z9: 8 | AA9: 9 | AB9: 10 | AC9: Total | AD9: PS | AE9: WS | AF9: 1 | AG9: PS | AH9: WS | AI9: Grade | AJ9: Grade
B10: HIGHEST POSSIBLE SCORE | F10: 15 | G10: 10 | H10: 20 | I10: 10 | J10: 10 | K10: 15 | L10: 20 | M10: 10 | N10: 5 | O10: 10 | P10: =IF(COUNT($F10:$O10)=0,"",SUM($F10:$O10)) -> 125 | Q10: 100 | R10: 0.3 | S10: 20 | T10: 10 | U10: 20 | V10: 10 | W10: 20 | X10: 20 | AC10: =IF(COUNT($S10:$AB10)=0,"",SUM($S10:$AB10)) -> 100 | AD10: 100 | AE10: 0.5 | AF10: 25 | AG10: 100 | AH10: 0.2
B11: MALE
A12: 1 | B12: Ang Eli Noah, Adlawan | F12: 11 | G12: 7 | H12: 11 | I12: 9 | J12: 7 | K12: 12 | L12: 18 | M12: 6 | N12: 5 | O12: 9 | P12: =IF(COUNT($F12:$O12)=0,"",SUM($F12:$O12)) -> 95 | Q12: =IF(ISERROR(IF($P12="","",ROUND(($P12/$P$10)*$Q$10,2))),"",IF($P12="","",ROUND(($P12/$P$10)*$Q$10,2))) -> 76 | R12: =IF($Q12="","",ROUND($Q12*$R$10,2)) -> 22.8 | S12: 13 | T12: 10 | U12: 20 | V12: 10 | W12: 18 | X12: 20 | AC12: 88 | AD12: =IF(ISERROR(IF($AC12="","",ROUND(($AC12/$AC$10)*$AD$10,2))),"",IF($AC12="","",ROUND(($AC12/$AC$10)*$AD$10,2))) -> 88 | AE12: =IF($AD12="","",ROUND($AD12*$AE$10,2)) -> 44 | AF12: 19 | AG12: =IF(ISERROR(IF($AF12="","",ROUND(($AF12/$AF$10)*$AG$10,2))),"",IF($AF12="","",ROUND(($AF12/$AF$10)*$AG$10,2))) -> 76 | AH12: =IF($AG12="","",ROUND($AG12*$AH$10,2)) -> 15.2 | AI12: =IF(ISERROR(IF($AF12="","",ROUND(SUM($R12,$AE12,$AH12),2))),"",IF($AF12="","",ROUND(SUM($R12,$AE12,$AH12),2))) -> 82 | AJ12: =IF(ISERROR(IF($AF12="","",VLOOKUP(AI12,TRANSMUTATION_TABLE,4,TRUE))),"",IF($AF12="","",VLOOKUP(AI12,TRANSMUTATION_TABLE,4,TRUE))) -> 88
A13: 2 | B13: 2.Arcillas, Riley Crilo | F13: 14 | G13: 7 | H13: 10 | I13: 8 | J13: 10 | K13: 13 | L13: 17 | M13: 9 | N13: 4 | O13: 6 | P13: =IF(COUNT($F13:$O13)=0,"",SUM($F13:$O13)) -> 98 | Q13: =IF(ISERROR(IF($P13="","",ROUND(($P13/$P$10)*$Q$10,2))),"",IF($P13="","",ROUND(($P13/$P$10)*$Q$10,2))) -> 78.4 | R13: =IF($Q13="","",ROUND($Q13*$R$10,2)) -> 23.52 | S13: 10 | T13: 10 | U13: 17 | V13: 10 | W13: 18 | X13: 20 | AC13: =IF(COUNT($S13:$AB13)=0,"",SUM($S13:$AB13)) -> 85 | AD13: =IF(ISERROR(IF($AC13="","",ROUND(($AC13/$AC$10)*$AD$10,2))),"",IF($AC13="","",ROUND(($AC13/$AC$10)*$AD$10,2))) -> 85 | AE13: =IF($AD13="","",ROUND($AD13*$AE$10,2)) -> 42.5 | AF13: 22 | AG13: =IF(ISERROR(IF($AF13="","",ROUND(($AF13/$AF$10)*$AG$10,2))),"",IF($AF13="","",ROUND(($AF13/$AF$10)*$AG$10,2))) -> 88 | AH13: =IF($AG13="","",ROUND($AG13*$AH$10,2)) -> 17.6 | AI13: =IF(ISERROR(IF($AF13="","",ROUND(SUM($R13,$AE13,$AH13),2))),"",IF($AF13="","",ROUND(SUM($R13,$AE13,$AH13),2))) -> 83.62 | AJ13: =IF(ISERROR(IF($AF13="","",VLOOKUP(AI13,TRANSMUTATION_TABLE,4,TRUE))),"",IF($AF13="","",VLOOKUP(AI13,TRANSMUTATION_TABLE,4,TRUE))) -> 89
A14: 3 | B14: 3.Haspe, Matt Austin Canvas | F14: 15 | G14: 4 | H14: 9 | I14: 7 | J14: 5 | K14: 8 | L14: 12 | M14: 3 | N14: 3 | O14: 5 | P14: =IF(COUNT($F14:$O14)=0,"",SUM($F14:$O14)) -> 71 | Q14: =IF(ISERROR(IF($P14="","",ROUND(($P14/$P$10)*$Q$10,2))),"",IF($P14="","",ROUND(($P14/$P$10)*$Q$10,2))) -> 56.8 | R14: =IF($Q14="","",ROUND($Q14*$R$10,2)) -> 17.04 | S14: 15 | T14: 8 | U14: 20 | V14: 10 | W14: 19 | X14: 20 | AC14: =IF(COUNT($S14:$AB14)=0,"",SUM($S14:$AB14)) -> 92 | AD14: =IF(ISERROR(IF($AC14="","",ROUND(($AC14/$AC$10)*$AD$10,2))),"",IF($AC14="","",ROUND(($AC14/$AC$10)*$AD$10,2))) -> 92 | AE14: =IF($AD14="","",ROUND($AD14*$AE$10,2)) -> 46 | AF14: 17 | AG14: =IF(ISERROR(IF($AF14="","",ROUND(($AF14/$AF$10)*$AG$10,2))),"",IF($AF14="","",ROUND(($AF14/$AF$10)*$AG$10,2))) -> 68 | AH14: =IF($AG14="","",ROUND($AG14*$AH$10,2)) -> 13.6 | AI14: =IF(ISERROR(IF($AF14="","",ROUND(SUM($R14,$AE14,$AH14),2))),"",IF($AF14="","",ROUND(SUM($R14,$AE14,$AH14),2))) -> 76.64 | AJ14: =IF(ISERROR(IF($AF14="","",VLOOKUP(AI14,TRANSMUTATION_TABLE,4,TRUE))),"",IF($AF14="","",VLOOKUP(AI14,TRANSMUTATION_TABLE,4,TRUE))) -> 85
A15: 4 | B15: 4.Lacbain, Kylle Marx Lim | F15: 12 | G15: 10 | H15: 15 | I15: 6 | J15: 8 | K15: 10 | L15: 15 | M15: 7 | N15: 5 | O15: 6 | P15: =IF(COUNT($F15:$O15)=0,"",SUM($F15:$O15)) -> 94 | Q15: =IF(ISERROR(IF($P15="","",ROUND(($P15/$P$10)*$Q$10,2))),"",IF($P15="","",ROUND(($P15/$P$10)*$Q$10,2))) -> 75.2 | R15: =IF($Q15="","",ROUND($Q15*$R$10,2)) -> 22.56 | S15: 13 | T15: 10 | U15: 20 | V15: 10 | W15: 19 | X15: 20 | AC15: =IF(COUNT($S15:$AB15)=0,"",SUM($S15:$AB15)) -> 92 | AD15: =IF(ISERROR(IF($AC15="","",ROUND(($AC15/$AC$10)*$AD$10,2))),"",IF($AC15="","",ROUND(($AC15/$AC$10)*$AD$10,2))) -> 92 | AE15: =IF($AD15="","",ROUND($AD15*$AE$10,2)) -> 46 | AF15: 19 | AG15: =IF(ISERROR(IF($AF15="","",ROUND(($AF15/$AF$10)*$AG$10,2))),"",IF($AF15="","",ROUND(($AF15/$AF$10)*$AG$10,2))) -> 76 | AH15: =IF($AG15="","",ROUND($AG15*$AH$10,2)) -> 15.2 | AI15: =IF(ISERROR(IF($AF15="","",ROUND(SUM($R15,$AE15,$AH15),2))),"",IF($AF15="","",ROUND(SUM($R15,$AE15,$AH15),2))) -> 83.76 | AJ15: =IF(ISERROR(IF($AF15="","",VLOOKUP(AI15,TRANSMUTATION_TABLE,4,TRUE))),"",IF($AF15="","",VLOOKUP(AI15,TRANSMUTATION_TABLE,4,TRUE))) -> 89
A16: 5 | B16: 5.Laurio, Xeon Jae Chico | F16: 11 | G16: 9 | H16: 9 | I16: 8 | J16: 4 | K16: 9 | L16: 10 | M16: 6 | N16: 5 | O16: 7 | P16: =IF(COUNT($F16:$O16)=0,"",SUM($F16:$O16)) -> 78 | Q16: =IF(ISERROR(IF($P16="","",ROUND(($P16/$P$10)*$Q$10,2))),"",IF($P16="","",ROUND(($P16/$P$10)*$Q$10,2))) -> 62.4 | R16: =IF($Q16="","",ROUND($Q16*$R$10,2)) -> 18.72 | S16: 14 | T16: 10 | U16: 20 | V16: 10 | W16: 20 | X16: 20 | AC16: =IF(COUNT($S16:$AB16)=0,"",SUM($S16:$AB16)) -> 94 | AD16: =IF(ISERROR(IF($AC16="","",ROUND(($AC16/$AC$10)*$AD$10,2))),"",IF($AC16="","",ROUND(($AC16/$AC$10)*$AD$10,2))) -> 94 | AE16: =IF($AD16="","",ROUND($AD16*$AE$10,2)) -> 47 | AF16: 20 | AG16: =IF(ISERROR(IF($AF16="","",ROUND(($AF16/$AF$10)*$AG$10,2))),"",IF($AF16="","",ROUND(($AF16/$AF$10)*$AG$10,2))) -> 80 | AH16: =IF($AG16="","",ROUND($AG16*$AH$10,2)) -> 16 | AI16: =IF(ISERROR(IF($AF16="","",ROUND(SUM($R16,$AE16,$AH16),2))),"",IF($AF16="","",ROUND(SUM($R16,$AE16,$AH16),2))) -> 81.72 | AJ16: =IF(ISERROR(IF($AF16="","",VLOOKUP(AI16,TRANSMUTATION_TABLE,4,TRUE))),"",IF($AF16="","",VLOOKUP(AI16,TRANSMUTATION_TABLE,4,TRUE))) -> 88
A17: 6 | B17: 6.Napuran, Thom Brenden Martecio | F17: 14 | G17: 9 | H17: 16 | I17: 9 | J17: 10 | K17: 13 | L17: 17 | M17: 10 | N17: 5 | O17: 5 | P17: =IF(COUNT($F17:$O17)=0,"",SUM($F17:$O17)) -> 108 | Q17: =IF(ISERROR(IF($P17="","",ROUND(($P17/$P$10)*$Q$10,2))),"",IF($P17="","",ROUND(($P17/$P$10)*$Q$10,2))) -> 86.4 | R17: =IF($Q17="","",ROUND($Q17*$R$10,2)) -> 25.92 | S17: 15 | T17: 10 | U17: 20 | V17: 10 | W17: 19 | X17: 20 | AC17: =IF(COUNT($S17:$AB17)=0,"",SUM($S17:$AB17)) -> 94 | AD17: =IF(ISERROR(IF($AC17="","",ROUND(($AC17/$AC$10)*$AD$10,2))),"",IF($AC17="","",ROUND(($AC17/$AC$10)*$AD$10,2))) -> 94 | AE17: =IF($AD17="","",ROUND($AD17*$AE$10,2)) -> 47 | AF17: 22 | AG17: =IF(ISERROR(IF($AF17="","",ROUND(($AF17/$AF$10)*$AG$10,2))),"",IF($AF17="","",ROUND(($AF17/$AF$10)*$AG$10,2))) -> 88 | AH17: =IF($AG17="","",ROUND($AG17*$AH$10,2)) -> 17.6 | AI17: =IF(ISERROR(IF($AF17="","",ROUND(SUM($R17,$AE17,$AH17),2))),"",IF($AF17="","",ROUND(SUM($R17,$AE17,$AH17),2))) -> 90.52 | AJ17: =IF(ISERROR(IF($AF17="","",VLOOKUP(AI17,TRANSMUTATION_TABLE,4,TRUE))),"",IF($AF17="","",VLOOKUP(AI17,TRANSMUTATION_TABLE,4,TRUE))) -> 94
A18: 7 | B18: 7.Rosinas, Nathaniel John | F18: 12 | G18: 8 | H18: 10 | I18: 10 | J18: 10 | K18: 12 | L18: 11 | M18: 7 | N18: 5 | O18: 5 | P18: =IF(COUNT($F18:$O18)=0,"",SUM($F18:$O18)) -> 90 | Q18: =IF(ISERROR(IF($P18="","",ROUND(($P18/$P$10)*$Q$10,2))),"",IF($P18="","",ROUND(($P18/$P$10)*$Q$10,2))) -> 72 | R18: =IF($Q18="","",ROUND($Q18*$R$10,2)) -> 21.6 | S18: 15 | T18: 10 | U18: 20 | V18: 10 | W18: 10 | X18: 20 | AC18: =IF(COUNT($S18:$AB18)=0,"",SUM($S18:$AB18)) -> 85 | AD18: =IF(ISERROR(IF($AC18="","",ROUND(($AC18/$AC$10)*$AD$10,2))),"",IF($AC18="","",ROUND(($AC18/$AC$10)*$AD$10,2))) -> 85 | AE18: =IF($AD18="","",ROUND($AD18*$AE$10,2)) -> 42.5 | AF18: 15 | AG18: =IF(ISERROR(IF($AF18="","",ROUND(($AF18/$AF$10)*$AG$10,2))),"",IF($AF18="","",ROUND(($AF18/$AF$10)*$AG$10,2))) -> 60 | AH18: =IF($AG18="","",ROUND($AG18*$AH$10,2)) -> 12 | AI18: =IF(ISERROR(IF($AF18="","",ROUND(SUM($R18,$AE18,$AH18),2))),"",IF($AF18="","",ROUND(SUM($R18,$AE18,$AH18),2))) -> 76.1 | AJ18: =IF(ISERROR(IF($AF18="","",VLOOKUP(AI18,TRANSMUTATION_TABLE,4,TRUE))),"",IF($AF18="","",VLOOKUP(AI18,TRANSMUTATION_TABLE,4,TRUE))) -> 85
A19: 8 | B19: 8.Salazar, Ulrich Gabrielle Asaytona | F19: 15 | G19: 10 | H19: 15 | I19: 10 | J19: 10 | K19: 11 | L19: 18 | M19: 10 | N19: 5 | O19: 10 | P19: =IF(COUNT($F19:$O19)=0,"",SUM($F19:$O19)) -> 114 | Q19: =IF(ISERROR(IF($P19="","",ROUND(($P19/$P$10)*$Q$10,2))),"",IF($P19="","",ROUND(($P19/$P$10)*$Q$10,2))) -> 91.2 | R19: =IF($Q19="","",ROUND($Q19*$R$10,2)) -> 27.36 | S19: 15 | T19: 10 | U19: 20 | V19: 10 | W19: 20 | X19: 20 | AC19: =IF(COUNT($S19:$AB19)=0,"",SUM($S19:$AB19)) -> 95 | AD19: =IF(ISERROR(IF($AC19="","",ROUND(($AC19/$AC$10)*$AD$10,2))),"",IF($AC19="","",ROUND(($AC19/$AC$10)*$AD$10,2))) -> 95 | AE19: =IF($AD19="","",ROUND($AD19*$AE$10,2)) -> 47.5 | AF19: 22 | AG19: =IF(ISERROR(IF($AF19="","",ROUND(($AF19/$AF$10)*$AG$10,2))),"",IF($AF19="","",ROUND(($AF19/$AF$10)*$AG$10,2))) -> 88 | AH19: =IF($AG19="","",ROUND($AG19*$AH$10,2)) -> 17.6 | AI19: =IF(ISERROR(IF($AF19="","",ROUND(SUM($R19,$AE19,$AH19),2))),"",IF($AF19="","",ROUND(SUM($R19,$AE19,$AH19),2))) -> 92.46 | AJ19: =IF(ISERROR(IF($AF19="","",VLOOKUP(AI19,TRANSMUTATION_TABLE,4,TRUE))),"",IF($AF19="","",VLOOKUP(AI19,TRANSMUTATION_TABLE,4,TRUE))) -> 95
A20: 9 | B20: 9.Santos, Sean Daniel Diopines | F20: 12 | G20: 9 | H20: 18 | I20: 10 | J20: 9 | K20: 13 | L20: 18 | M20: 9 | N20: 5 | O20: 6 | P20: =IF(COUNT($F20:$O20)=0,"",SUM($F20:$O20)) -> 109 | Q20: =IF(ISERROR(IF($P20="","",ROUND(($P20/$P$10)*$Q$10,2))),"",IF($P20="","",ROUND(($P20/$P$10)*$Q$10,2))) -> 87.2 | R20: =IF($Q20="","",ROUND($Q20*$R$10,2)) -> 26.16 | S20: 14 | T20: 10 | U20: 20 | V20: 10 | W20: 18 | X20: 20 | AC20: =IF(COUNT($S20:$AB20)=0,"",SUM($S20:$AB20)) -> 92 | AD20: =IF(ISERROR(IF($AC20="","",ROUND(($AC20/$AC$10)*$AD$10,2))),"",IF($AC20="","",ROUND(($AC20/$AC$10)*$AD$10,2))) -> 92 | AE20: =IF($AD20="","",ROUND($AD20*$AE$10,2)) -> 46 | AF20: 22 | AG20: =IF(ISERROR(IF($AF20="","",ROUND(($AF20/$AF$10)*$AG$10,2))),"",IF($AF20="","",ROUND(($AF20/$AF$10)*$AG$10,2))) -> 88 | AH20: =IF($AG20="","",ROUND($AG20*$AH$10,2)) -> 17.6 | AI20: =IF(ISERROR(IF($AF20="","",ROUND(SUM($R20,$AE20,$AH20),2))),"",IF($AF20="","",ROUND(SUM($R20,$AE20,$AH20),2))) -> 89.76 | AJ20: =IF(ISERROR(IF($AF20="","",VLOOKUP(AI20,TRANSMUTATION_TABLE,4,TRUE))),"",IF($AF20="","",VLOOKUP(AI20,TRANSMUTATION_TABLE,4,TRUE))) -> 93
A21: 10 | B21: 10.Soriano, Zegen Khaleb C. | F21: 13 | G21: 9 | H21: 10 | I21: 9 | J21: 10 | K21: 12 | L21: 14 | M21: 3 | N21: 5 | O21: 5 | P21: =IF(COUNT($F21:$O21)=0,"",SUM($F21:$O21)) -> 90 | Q21: =IF(ISERROR(IF($P21="","",ROUND(($P21/$P$10)*$Q$10,2))),"",IF($P21="","",ROUND(($P21/$P$10)*$Q$10,2))) -> 72 | R21: =IF($Q21="","",ROUND($Q21*$R$10,2)) -> 21.6 | S21: 13 | T21: 10 | U21: 20 | V21: 10 | W21: 20 | X21: 20 | AC21: =IF(COUNT($S21:$AB21)=0,"",SUM($S21:$AB21)) -> 93 | AD21: =IF(ISERROR(IF($AC21="","",ROUND(($AC21/$AC$10)*$AD$10,2))),"",IF($AC21="","",ROUND(($AC21/$AC$10)*$AD$10,2))) -> 93 | AE21: =IF($AD21="","",ROUND($AD21*$AE$10,2)) -> 46.5 | AF21: 18 | AG21: =IF(ISERROR(IF($AF21="","",ROUND(($AF21/$AF$10)*$AG$10,2))),"",IF($AF21="","",ROUND(($AF21/$AF$10)*$AG$10,2))) -> 72 | AH21: =IF($AG21="","",ROUND($AG21*$AH$10,2)) -> 14.4 | AI21: =IF(ISERROR(IF($AF21="","",ROUND(SUM($R21,$AE21,$AH21),2))),"",IF($AF21="","",ROUND(SUM($R21,$AE21,$AH21),2))) -> 82.5 | AJ21: =IF(ISERROR(IF($AF21="","",VLOOKUP(AI21,TRANSMUTATION_TABLE,4,TRUE))),"",IF($AF21="","",VLOOKUP(AI21,TRANSMUTATION_TABLE,4,TRUE))) -> 89
A22: 11 | P22: =IF(COUNT($F22:$O22)=0,"",SUM($F22:$O22)) | Q22: =IF(ISERROR(IF($P22="","",ROUND(($P22/$P$10)*$Q$10,2))),"",IF($P22="","",ROUND(($P22/$P$10)*$Q$10,2))) | R22: =IF($Q22="","",ROUND($Q22*$R$10,2)) | AC22: =IF(COUNT($S22:$AB22)=0,"",SUM($S22:$AB22)) | AD22: =IF(ISERROR(IF($AC22="","",ROUND(($AC22/$AC$10)*$AD$10,2))),"",IF($AC22="","",ROUND(($AC22/$AC$10)*$AD$10,2))) | AE22: =IF($AD22="","",ROUND($AD22*$AE$10,2)) | AG22: =IF(ISERROR(IF($AF22="","",ROUND(($AF22/$AF$10)*$AG$10,2))),"",IF($AF22="","",ROUND(($AF22/$AF$10)*$AG$10,2))) | AH22: =IF($AG22="","",ROUND($AG22*$AH$10,2)) | AI22: =IF(ISERROR(IF($AF22="","",ROUND(SUM($R22,$AE22,$AH22),2))),"",IF($AF22="","",ROUND(SUM($R22,$AE22,$AH22),2))) | AJ22: =IF(ISERROR(IF($AF22="","",VLOOKUP(AI22,TRANSMUTATION_TABLE,4,TRUE))),"",IF($AF22="","",VLOOKUP(AI22,TRANSMUTATION_TABLE,4,TRUE)))
A23: 12 | P23: =IF(COUNT($F23:$O23)=0,"",SUM($F23:$O23)) | Q23: =IF(ISERROR(IF($P23="","",ROUND(($P23/$P$10)*$Q$10,2))),"",IF($P23="","",ROUND(($P23/$P$10)*$Q$10,2))) | R23: =IF($Q23="","",ROUND($Q23*$R$10,2)) | AC23: =IF(COUNT($S23:$AB23)=0,"",SUM($S23:$AB23)) | AD23: =IF(ISERROR(IF($AC23="","",ROUND(($AC23/$AC$10)*$AD$10,2))),"",IF($AC23="","",ROUND(($AC23/$AC$10)*$AD$10,2))) | AE23: =IF($AD23="","",ROUND($AD23*$AE$10,2)) | AG23: =IF(ISERROR(IF($AF23="","",ROUND(($AF23/$AF$10)*$AG$10,2))),"",IF($AF23="","",ROUND(($AF23/$AF$10)*$AG$10,2))) | AH23: =IF($AG23="","",ROUND($AG23*$AH$10,2)) | AI23: =IF(ISERROR(IF($AF23="","",ROUND(SUM($R23,$AE23,$AH23),2))),"",IF($AF23="","",ROUND(SUM($R23,$AE23,$AH23),2))) | AJ23: =IF(ISERROR(IF($AF23="","",VLOOKUP(AI23,TRANSMUTATION_TABLE,4,TRUE))),"",IF($AF23="","",VLOOKUP(AI23,TRANSMUTATION_TABLE,4,TRUE)))
A24: 13 | B24: ='INPUT DATA'!B24 -> FEMALE | P24: =IF(COUNT($F24:$O24)=0,"",SUM($F24:$O24)) | Q24: =IF(ISERROR(IF($P24="","",ROUND(($P24/$P$10)*$Q$10,2))),"",IF($P24="","",ROUND(($P24/$P$10)*$Q$10,2))) | R24: =IF($Q24="","",ROUND($Q24*$R$10,2)) | AC24: =IF(COUNT($S24:$AB24)=0,"",SUM($S24:$AB24)) | AD24: =IF(ISERROR(IF($AC24="","",ROUND(($AC24/$AC$10)*$AD$10,2))),"",IF($AC24="","",ROUND(($AC24/$AC$10)*$AD$10,2))) | AE24: =IF($AD24="","",ROUND($AD24*$AE$10,2)) | AG24: =IF(ISERROR(IF($AF24="","",ROUND(($AF24/$AF$10)*$AG$10,2))),"",IF($AF24="","",ROUND(($AF24/$AF$10)*$AG$10,2))) | AH24: =IF($AG24="","",ROUND($AG24*$AH$10,2)) | AI24: =IF(ISERROR(IF($AF24="","",ROUND(SUM($R24,$AE24,$AH24),2))),"",IF($AF24="","",ROUND(SUM($R24,$AE24,$AH24),2))) | AJ24: =IF(ISERROR(IF($AF24="","",VLOOKUP(AI24,TRANSMUTATION_TABLE,4,TRUE))),"",IF($AF24="","",VLOOKUP(AI24,TRANSMUTATION_TABLE,4,TRUE)))
A25: 14 | B25: ='INPUT DATA'!B25 -> 1. Algabre, Sophia Ysabelle Dagle | F25: 6 | G25: 5 | H25: 13 | I25: 9 | J25: 8 | K25: 8 | L25: 15 | M25: 5 | N25: 4 | O25: 7 | P25: =IF(COUNT($F25:$O25)=0,"",SUM($F25:$O25)) -> 80 | Q25: =IF(ISERROR(IF($P25="","",ROUND(($P25/$P$10)*$Q$10,2))),"",IF($P25="","",ROUND(($P25/$P$10)*$Q$10,2))) -> 64 | R25: =IF($Q25="","",ROUND($Q25*$R$10,2)) -> 19.2 | S25: 10 | T25: 9 | U25: 17 | V25: 10 | W25: 15 | X25: 20 | AC25: =IF(COUNT($S25:$AB25)=0,"",SUM($S25:$AB25)) -> 81 | AD25: =IF(ISERROR(IF($AC25="","",ROUND(($AC25/$AC$10)*$AD$10,2))),"",IF($AC25="","",ROUND(($AC25/$AC$10)*$AD$10,2))) -> 81 | AE25: =IF($AD25="","",ROUND($AD25*$AE$10,2)) -> 40.5 | AF25: 15 | AG25: =IF(ISERROR(IF($AF25="","",ROUND(($AF25/$AF$10)*$AG$10,2))),"",IF($AF25="","",ROUND(($AF25/$AF$10)*$AG$10,2))) -> 60 | AH25: =IF($AG25="","",ROUND($AG25*$AH$10,2)) -> 12 | AI25: =IF(ISERROR(IF($AF25="","",ROUND(SUM($R25,$AE25,$AH25),2))),"",IF($AF25="","",ROUND(SUM($R25,$AE25,$AH25),2))) -> 71.7 | AJ25: =IF(ISERROR(IF($AF25="","",VLOOKUP(AI25,TRANSMUTATION_TABLE,4,TRUE))),"",IF($AF25="","",VLOOKUP(AI25,TRANSMUTATION_TABLE,4,TRUE))) -> 82
A26: 15 | B26: ='INPUT DATA'!B26 -> 2. Bade, Myel Ellyre, Bernales | F26: 15 | G26: 3 | H26: 8 | I26: 5 | J26: 5 | K26: 5 | L26: 13 | M26: 3 | N26: 5 | O26: 8 | P26: =IF(COUNT($F26:$O26)=0,"",SUM($F26:$O26)) -> 70 | Q26: =IF(ISERROR(IF($P26="","",ROUND(($P26/$P$10)*$Q$10,2))),"",IF($P26="","",ROUND(($P26/$P$10)*$Q$10,2))) -> 56 | R26: =IF($Q26="","",ROUND($Q26*$R$10,2)) -> 16.8 | S26: 15 | T26: 8 | U26: 19 | V26: 10 | W26: 18 | X26: 20 | AC26: =IF(COUNT($S26:$AB26)=0,"",SUM($S26:$AB26)) -> 90 | AD26: =IF(ISERROR(IF($AC26="","",ROUND(($AC26/$AC$10)*$AD$10,2))),"",IF($AC26="","",ROUND(($AC26/$AC$10)*$AD$10,2))) -> 90 | AE26: =IF($AD26="","",ROUND($AD26*$AE$10,2)) -> 45 | AF26: 18 | AG26: =IF(ISERROR(IF($AF26="","",ROUND(($AF26/$AF$10)*$AG$10,2))),"",IF($AF26="","",ROUND(($AF26/$AF$10)*$AG$10,2))) -> 72 | AH26: =IF($AG26="","",ROUND($AG26*$AH$10,2)) -> 14.4 | AI26: =IF(ISERROR(IF($AF26="","",ROUND(SUM($R26,$AE26,$AH26),2))),"",IF($AF26="","",ROUND(SUM($R26,$AE26,$AH26),2))) -> 76.2 | AJ26: =IF(ISERROR(IF($AF26="","",VLOOKUP(AI26,TRANSMUTATION_TABLE,4,TRUE))),"",IF($AF26="","",VLOOKUP(AI26,TRANSMUTATION_TABLE,4,TRUE))) -> 85
A27: 16 | B27: ='INPUT DATA'!B27 -> 3. Bangcal, Colynn Dela Rosa | F27: 14 | G27: 3 | H27: 17 | I27: 3 | J27: 10 | K27: 13 | L27: 18 | M27: 10 | N27: 5 | O27: 6 | P27: =IF(COUNT($F27:$O27)=0,"",SUM($F27:$O27)) -> 99 | Q27: =IF(ISERROR(IF($P27="","",ROUND(($P27/$P$10)*$Q$10,2))),"",IF($P27="","",ROUND(($P27/$P$10)*$Q$10,2))) -> 79.2 | R27: =IF($Q27="","",ROUND($Q27*$R$10,2)) -> 23.76 | S27: 13 | T27: 10 | U27: 20 | V27: 10 | W27: 18 | X27: 20 | AC27: =IF(COUNT($S27:$AB27)=0,"",SUM($S27:$AB27)) -> 91 | AD27: =IF(ISERROR(IF($AC27="","",ROUND(($AC27/$AC$10)*$AD$10,2))),"",IF($AC27="","",ROUND(($AC27/$AC$10)*$AD$10,2))) -> 91 | AE27: =IF($AD27="","",ROUND($AD27*$AE$10,2)) -> 45.5 | AF27: 20 | AG27: =IF(ISERROR(IF($AF27="","",ROUND(($AF27/$AF$10)*$AG$10,2))),"",IF($AF27="","",ROUND(($AF27/$AF$10)*$AG$10,2))) -> 80 | AH27: =IF($AG27="","",ROUND($AG27*$AH$10,2)) -> 16 | AI27: =IF(ISERROR(IF($AF27="","",ROUND(SUM($R27,$AE27,$AH27),2))),"",IF($AF27="","",ROUND(SUM($R27,$AE27,$AH27),2))) -> 85.26 | AJ27: =IF(ISERROR(IF($AF27="","",VLOOKUP(AI27,TRANSMUTATION_TABLE,4,TRUE))),"",IF($AF27="","",VLOOKUP(AI27,TRANSMUTATION_TABLE,4,TRUE))) -> 90
A28: 17 | B28: ='INPUT DATA'!B28 -> 4. Caballero, Amber Yasha, Omambac | F28: 12 | G28: 5 | H28: 15 | I28: 9 | J28: 9 | K28: 14 | L28: 15 | M28: 6 | N28: 5 | O28: 4 | P28: =IF(COUNT($F28:$O28)=0,"",SUM($F28:$O28)) -> 94 | Q28: =IF(ISERROR(IF($P28="","",ROUND(($P28/$P$10)*$Q$10,2))),"",IF($P28="","",ROUND(($P28/$P$10)*$Q$10,2))) -> 75.2 | R28: =IF($Q28="","",ROUND($Q28*$R$10,2)) -> 22.56 | S28: 10 | T28: 10 | U28: 18 | V28: 10 | W28: 20 | X28: 20 | AC28: =IF(COUNT($S28:$AB28)=0,"",SUM($S28:$AB28)) -> 88 | AD28: =IF(ISERROR(IF($AC28="","",ROUND(($AC28/$AC$10)*$AD$10,2))),"",IF($AC28="","",ROUND(($AC28/$AC$10)*$AD$10,2))) -> 88 | AE28: =IF($AD28="","",ROUND($AD28*$AE$10,2)) -> 44 | AF28: 19 | AG28: =IF(ISERROR(IF($AF28="","",ROUND(($AF28/$AF$10)*$AG$10,2))),"",IF($AF28="","",ROUND(($AF28/$AF$10)*$AG$10,2))) -> 76 | AH28: =IF($AG28="","",ROUND($AG28*$AH$10,2)) -> 15.2 | AI28: =IF(ISERROR(IF($AF28="","",ROUND(SUM($R28,$AE28,$AH28),2))),"",IF($AF28="","",ROUND(SUM($R28,$AE28,$AH28),2))) -> 81.76 | AJ28: =IF(ISERROR(IF($AF28="","",VLOOKUP(AI28,TRANSMUTATION_TABLE,4,TRUE))),"",IF($AF28="","",VLOOKUP(AI28,TRANSMUTATION_TABLE,4,TRUE))) -> 88
A29: 18 | B29: ='INPUT DATA'!B29 -> 5.Calilan, Olivia Mula | F29: 14 | G29: 5 | H29: 15 | I29: 10 | J29: 10 | K29: 14 | L29: 16 | M29: 6 | N29: 5 | O29: 6 | P29: =IF(COUNT($F29:$O29)=0,"",SUM($F29:$O29)) -> 101 | Q29: =IF(ISERROR(IF($P29="","",ROUND(($P29/$P$10)*$Q$10,2))),"",IF($P29="","",ROUND(($P29/$P$10)*$Q$10,2))) -> 80.8 | R29: =IF($Q29="","",ROUND($Q29*$R$10,2)) -> 24.24 | S29: 10 | T29: 10 | U29: 18 | V29: 10 | W29: 19 | X29: 20 | AC29: =IF(COUNT($S29:$AB29)=0,"",SUM($S29:$AB29)) -> 87 | AD29: =IF(ISERROR(IF($AC29="","",ROUND(($AC29/$AC$10)*$AD$10,2))),"",IF($AC29="","",ROUND(($AC29/$AC$10)*$AD$10,2))) -> 87 | AE29: =IF($AD29="","",ROUND($AD29*$AE$10,2)) -> 43.5 | AF29: 22 | AG29: =IF(ISERROR(IF($AF29="","",ROUND(($AF29/$AF$10)*$AG$10,2))),"",IF($AF29="","",ROUND(($AF29/$AF$10)*$AG$10,2))) -> 88 | AH29: =IF($AG29="","",ROUND($AG29*$AH$10,2)) -> 17.6 | AI29: =IF(ISERROR(IF($AF29="","",ROUND(SUM($R29,$AE29,$AH29),2))),"",IF($AF29="","",ROUND(SUM($R29,$AE29,$AH29),2))) -> 85.34 | AJ29: =IF(ISERROR(IF($AF29="","",VLOOKUP(AI29,TRANSMUTATION_TABLE,4,TRUE))),"",IF($AF29="","",VLOOKUP(AI29,TRANSMUTATION_TABLE,4,TRUE))) -> 90
A30: 19 | B30: ='INPUT DATA'!B30 -> 6.Facundo, Aleena | F30: 11 | G30: 7 | H30: 9 | I30: 5 | J30: 7 | K30: 8 | L30: 14 | M30: 5 | N30: 5 | O30: 9 | P30: =IF(COUNT($F30:$O30)=0,"",SUM($F30:$O30)) -> 80 | Q30: =IF(ISERROR(IF($P30="","",ROUND(($P30/$P$10)*$Q$10,2))),"",IF($P30="","",ROUND(($P30/$P$10)*$Q$10,2))) -> 64 | R30: =IF($Q30="","",ROUND($Q30*$R$10,2)) -> 19.2 | S30: 7 | T30: 10 | U30: 17 | V30: 10 | W30: 10 | X30: 20 | AC30: =IF(COUNT($S30:$AB30)=0,"",SUM($S30:$AB30)) -> 74 | AD30: =IF(ISERROR(IF($AC30="","",ROUND(($AC30/$AC$10)*$AD$10,2))),"",IF($AC30="","",ROUND(($AC30/$AC$10)*$AD$10,2))) -> 74 | AE30: =IF($AD30="","",ROUND($AD30*$AE$10,2)) -> 37 | AF30: 15 | AG30: =IF(ISERROR(IF($AF30="","",ROUND(($AF30/$AF$10)*$AG$10,2))),"",IF($AF30="","",ROUND(($AF30/$AF$10)*$AG$10,2))) -> 60 | AH30: =IF($AG30="","",ROUND($AG30*$AH$10,2)) -> 12 | AI30: =IF(ISERROR(IF($AF30="","",ROUND(SUM($R30,$AE30,$AH30),2))),"",IF($AF30="","",ROUND(SUM($R30,$AE30,$AH30),2))) -> 68.2 | AJ30: =IF(ISERROR(IF($AF30="","",VLOOKUP(AI30,TRANSMUTATION_TABLE,4,TRUE))),"",IF($AF30="","",VLOOKUP(AI30,TRANSMUTATION_TABLE,4,TRUE))) -> 80
A31: 20 | B31: ='INPUT DATA'!B31 -> 7.Ferriols, Francine Faith | F31: 9 | G31: 5 | H31: 16 | I31: 5 | J31: 8 | K31: 11 | L31: 14 | M31: 6 | N31: 5 | O31: 6 | P31: =IF(COUNT($F31:$O31)=0,"",SUM($F31:$O31)) -> 85 | Q31: =IF(ISERROR(IF($P31="","",ROUND(($P31/$P$10)*$Q$10,2))),"",IF($P31="","",ROUND(($P31/$P$10)*$Q$10,2))) -> 68 | R31: =IF($Q31="","",ROUND($Q31*$R$10,2)) -> 20.4 | S31: 10 | T31: 10 | U31: 18 | V31: 10 | W31: 18 | X31: 20 | AC31: =IF(COUNT($S31:$AB31)=0,"",SUM($S31:$AB31)) -> 86 | AD31: =IF(ISERROR(IF($AC31="","",ROUND(($AC31/$AC$10)*$AD$10,2))),"",IF($AC31="","",ROUND(($AC31/$AC$10)*$AD$10,2))) -> 86 | AE31: =IF($AD31="","",ROUND($AD31*$AE$10,2)) -> 43 | AF31: 16 | AG31: =IF(ISERROR(IF($AF31="","",ROUND(($AF31/$AF$10)*$AG$10,2))),"",IF($AF31="","",ROUND(($AF31/$AF$10)*$AG$10,2))) -> 64 | AH31: =IF($AG31="","",ROUND($AG31*$AH$10,2)) -> 12.8 | AI31: =IF(ISERROR(IF($AF31="","",ROUND(SUM($R31,$AE31,$AH31),2))),"",IF($AF31="","",ROUND(SUM($R31,$AE31,$AH31),2))) -> 76.2 | AJ31: =IF(ISERROR(IF($AF31="","",VLOOKUP(AI31,TRANSMUTATION_TABLE,4,TRUE))),"",IF($AF31="","",VLOOKUP(AI31,TRANSMUTATION_TABLE,4,TRUE))) -> 85
A32: 21 | B32: ='INPUT DATA'!B32 -> 8.Tagalog, Eysa Duron | F32: 13 | G32: 3 | H32: 12 | I32: 7 | J32: 10 | K32: 11 | L32: 17 | M32: 9 | N32: 5 | O32: 5 | P32: =IF(COUNT($F32:$O32)=0,"",SUM($F32:$O32)) -> 92 | Q32: =IF(ISERROR(IF($P32="","",ROUND(($P32/$P$10)*$Q$10,2))),"",IF($P32="","",ROUND(($P32/$P$10)*$Q$10,2))) -> 73.6 | R32: =IF($Q32="","",ROUND($Q32*$R$10,2)) -> 22.08 | S32: 13 | T32: 9 | U32: 19 | V32: 10 | W32: 19 | X32: 20 | AC32: =IF(COUNT($S32:$AB32)=0,"",SUM($S32:$AB32)) -> 90 | AD32: =IF(ISERROR(IF($AC32="","",ROUND(($AC32/$AC$10)*$AD$10,2))),"",IF($AC32="","",ROUND(($AC32/$AC$10)*$AD$10,2))) -> 90 | AE32: =IF($AD32="","",ROUND($AD32*$AE$10,2)) -> 45 | AF32: 19 | AG32: =IF(ISERROR(IF($AF32="","",ROUND(($AF32/$AF$10)*$AG$10,2))),"",IF($AF32="","",ROUND(($AF32/$AF$10)*$AG$10,2))) -> 76 | AH32: =IF($AG32="","",ROUND($AG32*$AH$10,2)) -> 15.2 | AI32: =IF(ISERROR(IF($AF32="","",ROUND(SUM($R32,$AE32,$AH32),2))),"",IF($AF32="","",ROUND(SUM($R32,$AE32,$AH32),2))) -> 82.28 | AJ32: =IF(ISERROR(IF($AF32="","",VLOOKUP(AI32,TRANSMUTATION_TABLE,4,TRUE))),"",IF($AF32="","",VLOOKUP(AI32,TRANSMUTATION_TABLE,4,TRUE))) -> 88
